Workbook

Sheet 说明与总览
A1: new-api 菲律宾部署方案 · 部署清单与 5 天冲刺落地计划（2 人全职 + 每日 3 段）
A3: 项目信息
A4: 项目名称 | B4: new-api AI 网关（Go + React 单体二进制）· 菲律宾站部署
A5: 文档版本 | B5: v2.3 + 2026-10-08 实况回改 + 2026-10-12 与指南同步（容量口径修订 + 三项遗留决策定案；2026-10-12 按《阿里云国际站菲律宾部署_详细操作指南-v2.0》当日云侧实况逐格回改，依据见「修订要点」⑭）
A6: 编制日期 | B6: 2026-09-24
A7: 编制依据 | B7: impl_deploy.md 第七章「阿里云部署方案（菲律宾 + 泰国）」7.1–7.10 与第八章「SLA 99.95% 达成方案」8.1–8.6；本项目评审报告 部署方案评审-2026-09-23.md
A8: 主站点 | B8: 阿里云国际站 · 菲律宾 马尼拉 ap-southeast-6（承载菲律宾常态流量）
A9: 备 region | B9: 阿里云国际站 · 新加坡 ap-southeast-1（仅承载 PH 备工作负载；泰国备为二期，不共用本集群）
A10: 数据库策略 | B10: RDS PostgreSQL 高可用版【仅部署于马尼拉】；新加坡不部署任何数据库（含只读副本与 DTS）。备 region 经 RDS 公网地址 + TLS(verify-full) + IP 白名单读写马尼拉主库，不双写、无 DTS 链路
A11: 上游出口 | B11: 各 region NAT 固定 EIP 池直出上游（马尼拉 4 个 + 新加坡 4 个 = 8 个），不启用 GA；上游白名单 = 上述 8 个 EIP，须提交并逐一确认生效。GA 列为二期可选优化（原 v2.0「EIP -> GA -> 上游」与「EIP 提交白名单」自相矛盾，已按此口径收敛）
A12: 目标 SLA | B12: ≥ 99.95%（月度不可用预算 21.6 分钟）；判定口径与排除项见「里程碑与验收」SLA 指标口径与排除项
A13: 总工期 | B13: 5 个自然日（D1–D5），每天 3 个工作段（S1 上午 09:00–13:00 / S2 下午 14:00–18:00 / S3 晚间 19:00–23:00，晚间段为加班段）；2 人全职，共 15 个时段 / 120 人时产能，计划投入 113 人时（94.2%），仅保留 7 人时缓冲。⚠ 现行工期口径 = 1 人 × 4 天 / 8 个执行窗口（见指南 §0.2–§0.4），本表 5 天 / 2 人 / 15 段为 v2.3 历史口径，保留供追溯
A14: 关键前提（门禁 G0） | B14: T-5 前置项（企业实名认证、资源配额审批、域名 NS 生效、证书签发、云产品开通、RAM/审计预建）与 T-3 前置项（代码侧补建改造、备 region 容量与配额、连接数方案、SLA 口径、staging/perf 方案）必须全部完成；任一项未完成则 D1 不得启动
A15: 工期风险等级 | B15: 高：5 天口径利用率 94.2%，仅余 7 人时缓冲（约 1.75 段/人），且为连续 5 天 × 12 小时（含晚间加班段）作业；任一人阻塞/请假、任一外部依赖（配额审批、实名认证、代码侧改造交付）延期即直接顺延，无内部消化空间。缓解措施与可选替代方案见「里程碑与验收」风险表、裁剪预案与工期口径变更说明。三项遗留决策已于 2026-09-24 定案：① 保留 D4/D5 国庆窗口，不采用顺延至 2026-10-08 的方案，改为锁定假期值班与工单加急；② T-5 = 2026-09-23 已过，本次不改基准、不顺延 D1；③ 本期不增加第 3 人，人力冗余风险由 A/B 互备与裁剪预案收敛。三项均为风险自担项，处置与残余风险见「里程碑与验收」风险表 A13 / A16 / A28 行。
... A18: 修订要点（v2.0 -> v2.3） | B18: ① 工期 5 天 -> 9 天（v2.0 -> v2.1：56 项任务压缩进 8 天/16 时段经 600 次重排无可行解）；② 前置期 T-3 的 0 天改为真实前置 T-5；③ 补 PgBouncer/RDS 代理、cluster-autoscaler、备 region HPA 与 1.5× 接管容量；④ 补 staging/perf、运维访问面、Tair 预热、PITR 演练、连接数预算、Grafana、带宽与成本量化、上游配额盘点；⑤ 安全 3 改（ALB 源收敛为 WAF/DCDN 回源段、支付回调源 IP 白名单、SESSION_SECRET 双密钥轮换）；⑥ 修正证书部署时序、依赖倒挂、J48 负荷公式、门禁计数与编号映射、域名/数据盘/RTT 阈值口径；⑦【v2.2】工期 9 天 -> 5 天：把每天 2 个半天时段改为 3 个工作段（新增 19:00–23:00 晚间加班段），15 时段 × 2 人 × 4 人时 = 120 人时产能，56 项任务在 15 段内重排完成、0 超载；⑧【v2.3】备 region 容量口径改为「本期仅承载 PH 备、不含泰国备」：节点数按 Pod requests 反算并留 ≥ 20% 系统组件余量 → 8 节点，节点池 2–12 改 2–8、配额 96 改 64 vCPU；统一「1.5×」基准为 maxReplicas × 1.5；⑨【2026-09-24 决策定案】三项遗留决策：保留 D4/D5 国庆窗口（不顺延）、T-5 = 2026-09-23 基准不动、本期不增加第 3 人。⑩【2026-10-08 按指南 v2.0（2026-10-07 版）实况回改】共回改 146 格：① 机型 g8i → g9i 首选（三机型列表，实开 g9ae）；② 主站 HPA 4–16 → 4–13、备站接管 16×1.5=24 → 13×1.5=19.5 → 20 副本；PDB minAvailable=3 → 70%；③ 新加坡配额实批按量 96 vCPU、节点池上限 12（v2.3 的 64 vCPU / 8 节点保留为容量下限）；④ RDS 规格 16C64G → pg.n4.2c.2m（2C8G，max_connections=800）；⑤ PgBouncer 自建 → RDS 内置托管池（F10 撤销）；⑥ 日志库 → 马尼拉 ClickHouse 企业版单 AZ（F9），不再购买新加坡 CK；⑦ 凭据链路 → 不使用 KMS/RRSA/ExternalSecret（2026-10-05 裁定），改手工 Opaque Secret；⑧ ECS 节点池付费方式定为按量 PostPaid（F13），成本按实况整机单价重算；⑨ 备站 Pod SQL_MAX_OPEN_CONNS=10（CM 100）；⑩ 伸缩组件实名 ack-goatscaler（非 cluster-autoscaler，观测入口 cm/kube-system/autoscaler-meta）；⑪ 任务 53 收敛口径由「30s × 节点数」改为「≤30 s（与节点数、跨 region 无关）」；⑫ 健康检查路径 /api/status 与全局限流冲突（应改 /readyz 并免限流）；⑬ 落地计划 AC 列按实况回填（21 张已完成 / 8 张部分交付 / 27 张未开始）。⑭【2026-10-12 与指南同步】：① G5 证书闭环——实购 Alibaba 品牌 DV 通配符 ali.dv.w（US$207，CertIdentifier=606823-ap-southeast-1，SAN *.likha.hk + likha.hk，链至 DigiCert Global Root G2），原 GlobalSign OV（US$997）已全额退款；⚠ 单张有效期仅 198 天（→ 2027-04-28）且 **AutoReissue=enable**（2026-10-12 经授权 UpdateInstance 开启，GetInstanceDetail 与 ListInstances 双路回读；写前 disable）⇒ 实例级托管续签已开，但 ALB 无 CAS 部署联动（实测 ListDeploymentJob、ListCloudResources(alb) 全空）⇒ 新证书仍须人工换绑两地 HTTPS 监听（2027-03-29 前，动作见 deploy/cert/targets.yaml R1–R4）；② 两地 ALB 443 监听 + 证书 + HTTP→HTTPS 301 已落地并验收（任务 19 V1–V5 全过、任务 25 闭合），requestTimeout 口径 180s → 600s（ALB 硬上限）；③ WAF 仍未接入（账号无实例；版本由「企业版」改为待裁定，2026-10-10 选型建议高级版）；④ GTM 仍挂起（任务 21，2026-09-30 裁定）；⑤ 备站跨区写马尼拉 CK 已实测在位（PUBLIC 端点 + sg_eip 白名单，2026-10-09 复核），原「待裁定」闭合；⑥ 任务 26 观测 4/4 闭环、任务 27 canary V1–V6 全过、任务 53 按更正判据通过；⑦ 镜像前缀按实测 EE 域名更正（B27）。⑮【2026-10-12 WAF 购买决策】：项目负责人裁定本次部署**不购买 WAF 3.0**（暂缓、非取消）——最低档高级版 3,880 元/月 ≈US$556 + 2,000 QPS + 日志服务单独起购，相对当前业务量过高，且实例只能控制台订阅（waf-openapi 无 CreateInstance、CLI 不能报价下单）。连锁更正：任务 20 整体挂起、V1–V4 从上线门禁移出；任务 47「ALB 入向不收敛」失去 WAF 缓解（443 直接暴露公网、无前置 L7 层，收敛与否重开为待裁定）；任务 40 证书部署对象只剩 ALB；任务 48 回调防线确定为两层（应用白名单 + 签名）；任务 52 成本表 WAF 行归零；M3 通过标准去掉 WAF；备站接管后同样无 L7 防护（任务 25 坑 2 转为知情接受风险）；CC 攻击的损失形态改为 HPA 按量扩容 + ALB LCU + 上游 token，故预算 80% 告警与异常突增巡检升为必须项。复评触发条件＝日请求量显著增长 / 出现真实攻击或 CC 事件。依据＝指南 §0.5 F15（2026-10-12 裁定）。
A19: 假设与关键参数（黄色底单元格需按实际情况确认/替换）
A20: 参数 | B20: 取值
A21: 部署启动日（D1，落地计划日期基准） | B21: 46293
A22: 前置启动日（T-5，账号/配额/域名/证书/产品开通须在此日发起） | B22: 46288
A23: 投入人力 | B23: 2 人全职 —— 人员A：基础设施/网络/接入/SRE；人员B：数据/应用/CI-CD/DevOps（已决策 2026-09-24：本期不增加第 3 人）
A24: 人力模型 | B24: 每时段 = 4 小时，单人每时段上限 4 人时；每天 3 个时段 = 2 人 × 12 小时 = 24 人时/天；5 天共 15 个时段（S1–S15）= 120 人时产能。（对比：v2.1 的 9 天口径为 2 人 × 8 小时/天 × 9 天 = 144 人时）。已决策（2026-09-24）：本期维持 2 人、不增加第 3 人，7 人时缓冲（94.2% 利用率）为可接受的剩余风险。
A25: 业务域名（统一口径，需替换为正式域名） | B25: www.likha.hk（全表统一；替代原 example-ph.com 示例）；备站公网入口 sg.likha.hk（2026-10-09 裁定新增，仅接管/直连，不进 GTM 池）
A26: 运维域名（统一口径） | B26: ops.likha.hk
A27: 镜像仓库前缀 | B27: acr-newapi-mnl-registry-vpc.ap-southeast-6.cr.aliyuncs.com/newapi-prod/new-api（2026-10-12 按指南 F8/§2 更正：ACR 企业版域名带实例名前缀；旧 registry-vpc.ap-southeast-6.aliyuncs.com/newapi/ 为个人版形态，命名空间 newapi 实测不存在）；⚠ 现网主镜像仓库实名 newapi-prod/newapi-master，本行 new-api 属任务 16 未回填的单仓口径待办
A28: 单实例规格 | B28: ecs.g9i.2xlarge（8 vCPU / 32 GiB，**首选**）；节点池实配三机型列表 [g9i.2xlarge, g8ine.2xlarge, g9ae.2xlarge]，2026-10-05 实际开出 4 台 **ecs.g9ae.2xlarge**（g8i 全系未在马尼拉上架）。Pod request 2 vCPU / 4 GiB，limit 4 vCPU / 8 GiB
A29: 负载与副本口径 | B29: 主站 stable 常态 4 副本、HPA **4–13**（2026-10-06 二次裁定：`limits.cpu 64` 下真实天花板 13，原 4–16 顶不到）；PDB minAvailable 70%。备 region PH 备常态 2 副本、HPA **2–20**（接管上限 = 主站 maxReplicas 13 × 1.5 = 19.5 → 20 副本）
A30: 节点池与配额口径 | B30: 马尼拉：常态 4 节点 / 自动伸缩 4–8（8 × 8 vCPU = 64，等于按量配额上限，顶满零余量）；新加坡：常态 2 节点 / 自动伸缩 2–12（实况配额 96/96 vCPU，顶满零余量）。本期仅承载 PH 备：接管 20 副本 × Pod request 2 vCPU = 40 vCPU，÷ (7.9 × 0.8 = 6.32) ≈ 6.3 → 7 节点 ⇒ v2.3 的「8 节点 / 64 vCPU」反算仍成立（容量下限），实况上限为 12 节点 / 96 vCPU，属历史余量；二期引入 TH 备前须重核
A31: 上游出口与白名单 | B31: 马尼拉 NAT EIP ×4 + 新加坡 NAT EIP ×4；均提交上游做 IP 白名单（不启用 GA）
A32: 日期口径：D1 = 部署启动日（2026-09-28），落地计划中每项任务的日期均由此基准自动推算；任务均为「工作段」粒度，D1 上午 = S1、D1 下午 = S2、D1 晚间 = S3 …… D5 晚间 = S15；每天 3 段 = 上午 09:00–13:00 / 下午 14:00–18:00 / 晚间 19:00–23:00（晚间为加班段，建议仅排低风险任务，关键变更与上线操作集中在 S1/S2）。数据来源：资源规格、数量与关键配置取自 impl_deploy.md 第 7.2 / 7.4 / 7.9 / 8.5 节；人时与配额为估算口径，需按实际情况与团队熟练度校准。前置期口径：T-5 = 2026-09-23（编制日 2026-09-24 时该时点已过）；经 2026-09-24 决策保持原基准不变、不顺延 D1，前置项（G1–G13）若未在本基准内闭环，仍按门禁规则顺延 D1（见风险表 A13 行）。
A34: 清单结构
A35: ① 账号与域名申请 | B35: 19 项前置申请：国际站注册与企业实名、支付与配额（备 region 规划 ≥64 vCPU，**实批按量 96 vCPU**）、RAM/MFA/审计、11 类云产品开通（**KMS 凭据管家不采购**）、域名实名与 NS 托管、SSL 证书、告警通道；标注【T-5 / T-3 前置】与等待时长；★ 门禁项 12 项与门禁清单 G1–G13 的映射见门禁清单「门禁作用」列
A36: ② 资源清单-马尼拉 | B36: 主站点（ap-southeast-6）39 项资源：网络、接入、计算、数据、缓存、日志、存储、安全、观测，以及 master / stable / canary 三个工作负载；新增 **RDS 内置托管 PgBouncer（F10 撤销自建）**、**ack-goatscaler（ACK 托管弹性组件）**、证书部署与 SNI 校验、staging/perf、支付回调白名单、连接数预算、出口带宽规格、Grafana、运维访问面、成本看板
A37: ③ 资源清单-新加坡 | B37: 备 region（ap-southeast-1）20 项资源：【RDS 数量为 0，不部署】；新增节点池自动伸缩与 PH 备 HPA（接管上限 = 主站 maxReplicas **13 × 1.5 = 19.5 → 20 副本**）。本期仅承载 PH 备（泰国备为二期、不共用本集群），节点池反算下限 8 节点 / 64 vCPU，实况上限 12 节点 / 96 vCPU
A38: ④ 网络与安全规划 | B38: VPC/vSwitch 网段、EIP 规划、安全组逐条规则（入向禁止 0.0.0.0/0，仅放行 WAF/DCDN 回源段与对端 CIDR）、**凭据与轮换周期（2026-10-05 裁定不使用 KMS：手工 Opaque Secret 注入；SESSION_SECRET 双密钥过渡）**
A39: ⑤ 落地计划 | B39: 5 天 56 项任务，按 D1–D5 × 上午/下午/晚间共 15 个时段排布；含负责人员、前置依赖、人时、甘特条、验收标准，并附【T-5/T-3 前置门禁清单】与【人力负荷校验】（每时段单人 ≤ 4 人时）。（⚠ 现行工期口径 = 1 人 × 4 天，见指南 §0.2–§0.4）
A40: ⑥ 里程碑与验收 | B40: G0 门禁 + M1–M5 里程碑、验收证据、SLA 指标口径与排除项、15 项关键风险、7 项工期裁剪预案

Sheet 账号与域名申请
A1: 阿里云国际站 · 账号、实名、配额与域名申请清单（★ = 阻塞 D1 启动的 T-5 / T-3 前置项）
A3: 序号 | B3: 类别 | C3: 事项 | D3: 入口 / 平台 | E3: 关键要求与参数 | F3: 前置依赖 | G3: 负责角色 | H3: 启动时点 | I3: 工期 / 等待时长 | J3: 是否门禁项 | K3: 备注
A4: 1 | B4: 账号注册 | C4: 注册阿里云国际站账号 | D4: alibabacloud.com | E4: 企业域名邮箱注册；注册国家/地区选 Philippines；绑定可接收国际短信的手机号 | F4: — | G4: 项目负责人 | H4: T-5 前置 | I4: 0.5 工作日 | J4: ★ 门禁 | K4: 主账号仅用于计费与 RAM 管理，禁止日常运维使用
A5: 2 | B5: 账号注册 | C5: 完成企业实名认证 | D5: 阿里云国际站 · 实名认证 | E5: 提交菲律宾主体注册文件（DTI/SEC）、法人身份证件、公司地址证明；名称须与银行账户一致 | F5: 1 | G5: 项目负责人 | H5: T-5 前置 | I5: 1–2 工作日（等待） | J5: ★ 门禁 | K5: 未实名无法购买 ECS/RDS；5 天工期最大外部风险，须 T-5 立即提交并每日跟进
A6: 3 | B6: 账号注册 | C6: 开通后付费并绑定支付方式 | D6: 费用中心 · 支付方式 | E6: 绑定 Visa/MasterCard 企业卡或对公转账；开启自动扣款与余额告警 | F6: — | G6: 财务 | H6: T-5 前置 | I6: 0.5 工作日 | J6: ★ 门禁 | K6: 预留不低于 3 个月账单的信用额度，避免欠费停机
A7: 4 | B7: 账号安全 | C7: 主账号安全加固 | D7: 账号中心 · 安全设置 | E7: 开启 MFA、登录保护与异地登录告警；绑定安全邮箱与紧急联系人 | F7: 1 | G7: 安全负责人 | H7: T-5 前置 | I7: 0.5 工作日 | J7: — | K7: OWASP：主账号不做日常操作
A8: 5 | B8: 账号安全 | C8: 创建 RAM 用户与最小权限策略 | D8: RAM 控制台 | E8: 4 个角色：admin、ops、cicd-push（仅 ACR 推送）、iac-terraform（IaC 最小权限） | F8: 4 | G8: 安全负责人 | H8: T-5 前置 | I8: 0.5 工作日 | J8: ★ 门禁 | K8: 同时开启 ActionTrail，记录全部云 API 变更并保留 180 天
A9: 6 | B9: 账号安全 | C9: 配置资源组与成本标签 | D9: 资源管理 / 费用中心 | E9: 资源组按 site=ph-mnl、site=sg 划分；成本标签：项目、环境、站点、成本中心 | F9: 5 | G9: 运维负责人 | H9: T-5 前置 | I9: 0.5 工作日 | J9: — | K9: 用于分账、预算告警与成本核算
A10: 7 | B10: 配额申请 | C10: 提交资源配额（Quota）申请 | D10: 配额中心 / 工单 | E10: ECS vCPU ≥ 64（马尼拉，实批 64）+ ≥ 64（新加坡，实批按量 96；备 region 接管上限 = 主站 maxReplicas 13 × 1.5 = 19.5 → 20 副本 → 40 vCPU，容量下限 8 节点 / 64 vCPU）；ALB 2；EIP ≥ 10；RDS PostgreSQL 高可用版（pg.n4.2c.2m = 2C/8G，实况）；RDS 内置托管 PgBouncer（实例上已启用，无需单独配额）；Tair 4GB 主备；ClickHouse **企业版单 AZ** 2 节点；OSS 2；GTM 1 | F10: 1 | G10: 运维负责人 | H10: T-5 前置 | I10: 2–3 工作日（等待，关键路径） | J10: ★ 门禁 | K10: 国际站默认配额常不足；工单需说明业务场景与峰值，分两批（先马尼拉后新加坡）申请。新加坡 ≥64 vCPU 的依据是「单站点全量接管 = 被接管站点 maxReplicas 13 × 1.5 = 19.5 → 20 副本」：20 × Pod request 2 vCPU = 40 vCPU，÷ (7.9 × 0.8 = 6.32) ≈ 6.3 → 7 节点，留余量取 8 节点 = 64 vCPU。**实批为按量口径 96 vCPU（q_ecs_enterprise_postpay_c，2026-10-06 裁定后为核量口径），节点池上限 12 ⇒ 顶满即零余量**。【分期口径】本期新加坡仅承载 PH 备、不含泰国备，因此不按「PH 备 + TH 备 同时接管」的 96 vCPU（含 ≥20% 系统组件余量即 ≥16 节点 / 128 vCPU）申请；二期引入 TH 备时须重新提工单
A11: 8 | B11: 产品开通 | C11: 开通网络与计算类产品 | D11: 产品控制台 | E11: VPC、EIP、NAT 网关、ALB、ACK Pro 托管版（含节点池自动伸缩）、ACR 企业版 | F11: 1 | G11: 运维负责人 | H11: T-5 前置 | I11: 0.5 工作日 | J11: ★ 门禁 | K11: 国际站需逐个产品单独开通
A12: 9 | B12: 产品开通 | C12: 开通数据与缓存类产品 | D12: 产品控制台 | E12: RDS PostgreSQL 17（HighAvailability，pg.n4.2c.2m = 2C/8G，max_connections=800 用户不可改）、**RDS 内置托管 PgBouncer（PGBouncerEnabled=true，自建方案 F10 已撤销）**、Tair（Redis 兼容）、云数据库 ClickHouse **企业版（单可用区，马尼拉仅 ap-southeast-6a）** | F12: 1 | G12: 运维负责人 | H12: T-5 前置 | I12: 0.5 工作日 | J12: ★ 门禁 | K12: ClickHouse 仅承载 LOG_SQL_DSN；企业版**只有按量付费**（Serverless 商品类型，不支持包年包月），等价降本手段 = 计算资源包（马尼拉抵扣因子 1.45）；马尼拉 CK 可用区只有 6a、存储只有 OSS
A13: 10 | B13: 产品开通 | C13: 开通接入与安全类产品 | D13: 产品控制台 | E13: 云解析 DNS（旗舰版）、GTM（旗舰版）、DCDN、WAF 3.0（⏸ 2026-10-12 裁定**本轮不采购**，暂缓非取消；账号无实例，指南 F15）、SSL 证书、堡垒机 / VPN（**KMS 凭据管家：2026-10-05 裁定不采购**） | F13: 1 | G13: 运维负责人 | H13: T-5 前置 | I13: 0.5 工作日 | J13: ★ 门禁 | K13: ⏸ 2026-10-12 裁定（指南 F15）：**本次部署不购买 WAF 3.0**（暂缓）——最低档高级版 3,880 元/月 ≈US$556 + 2,000 QPS + 日志服务单独起购，相对当前业务量过高；实例本就只能控制台订阅（waf-openapi 无 CreateInstance、无报价条目）。复评触发＝日请求量增长 / 出现真实攻击或 CC 事件；复评时选型结论仍按 2026-10-10 文档（高级版够用、基础版不可用、日志服务单独起购）。证书 G5 已于 2026-10-12 闭环签发
A14: 11 | B14: 产品开通 | C14: 开通可观测与审计类产品 | D14: 产品控制台 | E14: SLS、ARMS（Prometheus 版 + 应用监控）、Grafana 服务 / 工作区、云监控站点监控、ActionTrail | F14: 1 | G14: 运维负责人 | H14: T-5 前置 | I14: 0.5 工作日 | J14: — | K14: 拨测点选马尼拉、曼谷、新加坡、东京、香港
... A22: 19 | B22: 通知 | C22: 配置告警通道与联系人 | D22: 云监控 / ARMS | E22: 钉钉或企业微信机器人 + 短信 + 电话；P1 走电话并建立值班表 | F22: 11 | G22: 运维负责人 | H22: D5 下午（S14） | I22: 见落地计划 #32 | J22: — | K22: 告警联系人须包含 2 名执行人与项目负责人
C24: ★ 门禁项共 12 项（J 列标 ★ 的行）， 全部为前期等待型前置：其中 #1/#2/#3/#5/#7–#10/#13–#15/#17 为 T-5 前置，#7 的新加坡配额补充与代码侧补建（G8）为 T-3 前置。 ★ 项与门禁清单 G1–G13 的一一映射见「落地计划」门禁清单「门禁作用」列。G0 门禁未通过则 D1 不得启动。

Sheet 资源清单-马尼拉
A1: 菲律宾主站点资源清单 · ap-southeast-6（马尼拉）
A3: 序号 | B3: 层 | C3: 资源 / 产品 | D3: 规格与版本 | E3: 数量 | F3: 命名规范 | G3: 地域 / 可用区 | H3: 关键配置 | I3: 前置依赖 | J3: 申请方式 | K3: 落地日 | L3: 负责 | M3: 备注
A4: 1 | B4: 网络 | C4: VPC | D4: 10.0.0.0/16 | E4: 1 | F4: vpc-newapi-mnl-prod | G4: ap-southeast-6 | H4: 单 VPC；开启 DNS 主机名解析；VPC 流日志投递 SLS | I4: — | J4: 控制台/IaC | K4: D1 | L4: 人员A | M4: 与新加坡网段不重叠
A5: 2 | B5: 网络 | C5: vSwitch（公共） | D5: 2 × /24 | E5: 2 | F5: vsw-mnl-pub-a / vsw-mnl-pub-b | G5: 可用区 A / B | H5: ALB 与 NAT 网关使用 | I5: 1 | J5: 控制台/IaC | K5: D1 | L5: 人员A | M5: 多可用区是高可用前提
A6: 3 | B6: 网络 | C6: vSwitch（私有） | D6: 4 × /20 | E6: 4 | F6: vsw-mnl-app-a/b、vsw-mnl-data-a/b | G6: 跨 2 个可用区 | H6: Pod 使用 app 网段，RDS 使用 data 网段 | I6: 1 | J6: 控制台/IaC | K6: D1 | L6: 人员A | M6: Pod 与数据库分网段便于隔离
A7: 4 | B7: 网络 | C7: NAT 网关 | D7: 多可用区 | E7: 1 | F7: nat-mnl-prod | G7: 跨 2 个可用区 | H7: 绑定固定 EIP 池；仅私有子网可出网 | I7: 1 | J7: 控制台/IaC | K7: D1 | L7: 人员A | M7: 供应商 IP 白名单依赖固定 EIP
A8: 5 | B8: 网络 | C8: EIP（上游出口白名单池） | D8: ≥ 4 个 | E8: 4 | F8: eip-mnl-upstream-01..04 | G8: 多可用区 | H8: 绑定 NAT 网关；用于供应商白名单（本次出口直出、不启用 GA） | I8: 4 | J8: 控制台/IaC | K8: D1 | L8: 人员A | M8: 同一池也是备 region 访问 RDS 的白名单来源；8 个 EIP 均须提交上游并确认生效
A9: 6 | B9: 接入 | C9: ALB | D9: 标准版 II | E9: 1 | F9: alb-newapi-mnl | G9: 跨 2 个可用区 | H9: 实况（2026-10-12）：HTTP:80 + HTTPS:443 两监听（443 = lsn-hjl2cz2g9oqvee4eix，证书 606823-ap-southeast-1，tls_cipher_policy_1_2_strict_with_1_3）+ Ingress/new-api-http-redirect（order=1）做 HTTP→HTTPS 301；idleTimeout=60s；requestTimeout=600s（原口径 180s；600 为 ALB 硬上限）；TLS 1.2+1.3；健康检查 GET /api/status @20s（原 6s，2026-10-06 改）**与全局限流 360/180s per client IP 冲突 ⇒ 必须改 /readyz 并免限流（G8）** | I9: 2,17(前置) | J9: 控制台/IaC | K9: D2 | L9: 人员A | M9: SSE 靠网关 ping（15–20s）保活
A10: 7 | B10: 接入 | C10: WAF 3.0 | D10: ⏸ 2026-10-12 裁定（F15）：本轮**不采购**（暂缓，非取消）；依据＝指南 §0.5 F15（2026-10-12 裁定）。复评条件＝业务量增长 / 真实攻击或 CC 事件 | E10: 1 | F10: waf-newapi-mnl | G10: 马尼拉 | H10: 接入 www.likha.hk；CC 阈值对齐 GLOBAL_API_RATE_LIMIT；放行支付回调路径并限定回调源 IP 段 —— ⚠ 2026-10-10 复核：账号无 WAF 实例、任务 20 五步 0 完成；ALB 云原生接入实为 SDK 集成（非透明代理），443 不是前置、且不占「可接入域名数」；选型与判据更正见 deploy/docs/WAF接入_CC攻击分类与计费选型_2026-10-10.md；⚠ 2026-10-12（F15）：本行**整体不执行**——本轮不采购 WAF ⇒ CC 频控只剩应用侧 GLOBAL_API_RATE_LIMIT 360/180s（它只按客户端 IP 计数，正是任务 53 的 429 源头）、回调豁免与 waf-log 投递同时取消，入口层证据链改由 alb-access SLS（sls-newapi-mnl/alb_access）承担 | I10: 6 | J10: 控制台 | K10: D4 | L10: 人员A | M10: 抗 L7
A11: 8 | B11: 接入 | C11: 云解析 DNS | D11: 旗舰版 | E11: 1 | F11: — | G11: 全球 | H11: 承载主域名与子域名解析 | I11: 15(前置) | J11: 控制台 | K11: D1 | L11: 人员A | M11: 与 GTM 配合完成按延迟解析
A12: 9 | B12: 接入 | C12: 全局流量管理 GTM | D12: 旗舰版 | E12: 1 | F12: gtm-newapi-ph | G12: 全球 | H12: 探测 GET /api/status 每 15s；故障切换目标 ≤ 60s（G8 落地后随健康检查一并改 /readyz；15 s 间隔本身不撞额度，但与 ALB 探测共用同一客户端 IP 键时须合并计预算） | I12: 6,17(前置) | J12: 控制台 | K12: D3 | L12: 人员A | M12: 故障切换目标 ≤ 60s
A13: 10 | B13: 接入 | C13: DCDN | D13: 按量付费 | E13: 1 | F13: dcdn-newapi-ph | G13: 全球 | H13: 静态资源加速；index.html no-cache；带指纹 chunk 缓存 7 天 | I13: 17(前置) | J13: 控制台 | K13: D2 | L13: 人员A | M13: 可按裁剪预案延后
A14: 11 | B14: 计算 | C14: ACK Pro 托管版 | D14: 控制面 SLA 99.95% | E14: 1 | F14: ack-newapi-mnl | G14: 多可用区 | H14: Kubernetes 1.31+；CNI Terway；开启 RRSA | I14: 7(前置) | J14: 控制台 | K14: D1 | L14: 人员A | M14: 需 ACK 配额已批复
A15: 12 | B15: 计算 | C15: ECS 节点池 | D15: ecs.g9i.2xlarge（8C32G，**首选**）；实配三机型列表 [g9i.2xlarge, g8ine.2xlarge, g9ae.2xlarge]，2026-10-05 实开 4 台 ecs.g9ae.2xlarge | E15: ≥ 4 | F15: ecs-mnl-node-01..04 | G15: 跨 2 个可用区 | H15: 系统盘 100G ESSD PL1 + 数据盘 300G ESSD；nofile=200000 | I15: 11 | J15: 控制台 | K15: D2 | L15: 人员A | M15: HPA min 4 / max **13**（2026-10-06 二次裁定；Pod request 2 vCPU / 4 GiB）；节点池自动伸缩 min 4 / max 8（按量 PostPaid，配额 64/64 ⇒ 顶满零余量）；13 副本需 ≥5 台节点；单 AZ 故障仍有 2 副本
A16: 13 | B16: 计算 | C16: ACR 企业版（马尼拉） | D16: 企业版实例 | E16: 1 | F16: acr-newapi-mnl | G16: ap-southeast-6 | H16: VPC 域名供集群拉取；开启镜像扫描与签名 | I16: 12(前置) | J16: 控制台 | K16: D1 | L16: 人员B | M16: 镜像 tag = git sha
A17: 14 | B17: 数据 | C17: RDS PostgreSQL 高可用版 | D17: PostgreSQL 17（实测 17.10）；pg.n4.2c.2m = 2C / 8G；max_connections = 800（用户不可改） | E17: 1 | F17: rds-mnl-newapi | G17: 主 A 备 B（跨可用区） | H17: PITR 7 天；每日全量 + WAL 归档 OSS；开启公网地址但仅放行新加坡 NAT EIP | I17: 9(前置) | J17: 控制台/IaC | K17: D1 | L17: 人员B | M17: 菲律宾唯一主库；⚠ 2026-10-12 实查：PayType=Prepaid 且仅 1 个月，ExpireTime=2026-10-28T16:00:00Z（距当日 16 天），Create/Expire 之间无续费台账 ⇒ 到期前须续费或开自动续费，否则主库停机
A18: 15 | B18: 数据 | C18: RDS 账号与数据库 | D18: — | E18: 2 | F18: newapi / newapi_sg | G18: 马尼拉 | H18: newapi：应用主账号；newapi_sg：备 region 接管账号（最小权限） | I18: 14 | J18: 控制台 | K18: D1 | L18: 人员B | M18: 禁止与备 region 共用超级账号
A19: 16 | B19: 数据 | C19: RDS 只读实例（可选） | D19: pg 15，同规格 | E19: 1 | F19: rds-mnl-newapi-ro | G19: 马尼拉 | H19: 报表与导出类查询分流 | I19: 14 | J19: 控制台 | K19: D2 | L19: 人员B | M19: 非必需，工期/成本紧张时按裁剪预案取消
A20: 17 | B20: 缓存 | C20: Tair（Redis 兼容） | D20: 主备版 4 GB | E20: 1 | F20: tair-mnl-newapi | G20: 多可用区 | H20: 密码 + 内网 ACL；maxmemory-policy allkeys-lru | I20: 4(前置) | J20: 控制台 | K20: D1 | L20: 人员B | M20: 生产建议升级集群版；⚠ 2026-10-12 实查：ChargeType=PrePaid 且仅 1 个月，EndTime=2026-10-28T16:00:00Z（与主库同日到期，无续费台账）
A21: 18 | B21: 日志 | C21: 云数据库 ClickHouse | D21: 企业版 · 单可用区（只支持 ap-southeast-6a）· 存储只有 OSS · 只有按量付费 | E21: 1 | F21: cc-5tsv2o51s1360b0pr（ck-mnl-newapi） | G21: 马尼拉 | H21: 仅承载 LOG_SQL_DSN；TTL 90 天；白名单 = 主站 app 两段 + 账号 newapi/ckadmin；库 newapi_logs（表 logs 20 列与代码 DDL 同构）；**LOG_SQL_DSN 已于 2026-10-05 注入两地集群并端到端鉴权通过**（sg 用 -public 端点） | I21: 9(前置) | J21: 控制台 | K21: D1 | L21: 人员B | M21: 写日志失败必须降级
A22: 19 | B22: 存储 | C22: OSS Bucket | D22: 标准 + 低频生命周期 | E22: 1 | F22: oss-newapi-mnl | G22: 马尼拉 | H22: 同城冗余 ZRS；版本控制；90 天转归档；防盗链 + 签名 URL | I22: 12(前置) | J22: 控制台 | K22: D1 | L22: 人员B | M22: 同时承载 RDS 备份归档
A23: 20 | B23: 安全 | C23: 凭据链路（不使用 KMS） | D23: 手工 Opaque Secret + 执行机保管目录 ~/.deploy_secrets（600） | E23: 1 | F23: —（无云侧资源） | G23: 马尼拉 | H23: 2026-10-05 裁定：不实施 KMS 凭据管家 / RRSA / ExternalSecret | I23: 10(前置) | J23: — | K23: —（不实施） | L23: 人员B | M23: 改由 deploy/task17_secret_inject.sh 以 kubectl create secret --from-literal 就地注入；轮转 = 两地人工双写 + 两次 rollout restart + 指纹核对（原「云端改一次自动跟随」的能力放弃）
A24: 21 | B24: 安全 | C24: 安全组与网络 ACL | D24: — | E24: — | F24: sg-mnl-alb / sg-mnl-app / sg-mnl-db | G24: 马尼拉 | H24: 端口最小化，规则详见「网络与安全规划」 | I24: 2,3,12 | J24: 控制台 | K24: D3 | L24: 人员A | M24: app 仅允许 ALB 访问 3000
A25: 22 | B25: 观测 | C25: SLS Project / LogStore | D25: 按量 | E25: 1 | F25: sls-newapi-mnl | G25: 马尼拉 | H25: 采集 stdout（容器日志实际落点 = ACK 自管项目 k8s-log-<clusterId>，mnl cd57e40c…）；应用文件日志实为 /data/logs/oneapi-*.log（由 CLI 参数 -log-dir 指定，非 env）；sys 30 天 / audit 180 天 | I25: 11 | J25: 控制台 | K25: D4 | L25: 人员A | M25: Logtail DaemonSet 采集；sls-newapi-mnl 仅承载云产品侧日志（alb_access 在写；rds-audit / actiontrail 近 7 天 count=0，真因 = RDS SQL 审计 Disabled + ActionTrail 按 F6 投递 OSS）
A26: 23 | B26: 观测 | C26: ARMS Prometheus + 应用监控 | D26: 按量 | E26: 1 | F26: arms-newapi-mnl | G26: 马尼拉 | H26: ServiceMonitor 抓 /metrics（需补建）；OpenTelemetry SDK（需补建） | I26: 11 | J26: 控制台 | K26: D4 | L26: 人员A | M26: 代码补建项须在 T-3 完成（门禁 G8）；**/readyz 必须免限流** —— 现用 /api/status 同时是 ALB 健康检查与 kubelet 探针路径，落在 GlobalAPIRateLimit（360/180s per IP）内，每源 IP 每窗口 480 条 ⇒ 已造成一次自伤重启（2026-10-06）
A27: 24 | B27: 观测 | C27: 云监控站点监控（拨测） | D27: 按量 | E27: 1 | F27: — | G27: 马尼拉 + 新加坡 + 东京 + 香港 | H27: 探测 GET /api/status，间隔 1 分钟，断言 success:true 与版本匹配 | I27: 11(前置) | J27: 控制台 | K27: D4 | L27: 人员A | M27: 真实用户视角可用性
A28: 25 | B28: 观测 | C28: 操作审计 ActionTrail | D28: 默认 | E28: 1 | F28: — | G28: 马尼拉 | H28: 记录全部云 API 变更，保留 180 天；运维访问面另见 #38。**实况：投递 OSS（newapi-audit-trail → oss-newapi-mnl），SLS 同名 Logstore 为预留占位** | I28: 5(前置) | J28: 控制台 | K28: D1 | L28: 人员A | M28: 合规与变更追溯
A29: 26 | B29: 工作负载 | C29: master Deployment | D29: — | E29: 1 | F29: new-api-master | G29: 马尼拉 | H29: NODE_TYPE=master；replicas=1；Recreate；独立 PVC（RWO）；不接 ALB 流量 | I29: 11,14 | J29: GitOps | K29: D2 | L29: 人员B | M29: 唯一执行 AutoMigrate 与 master-only 任务的节点
A30: 27 | B30: 工作负载 | C30: stable Deployment | D30: — | E30: 1 | F30: new-api-stable | G30: 跨 2 个可用区 | H30: replicas=4；maxUnavailable=0；PDB **minAvailable=70%**（现网：4 副本时 disruptionsAllowed=1；16 副本口径下比固定 3 更严）；HPA **4–13**；preStop sleep 15s；**必须显式钉 GOMAXPROCS=4**（容器内 nproc=8）；补 SESSION_COOKIE_SECURE + SESSION_COOKIE_TRUSTED_URL（须成对）与 RDS 根 CA 挂载 /etc/ssl/rds（Secret rds-ca-apse6） | I30: 26 | J30: GitOps | K30: D3 | L30: 人员B | M30: 滚动发布零停机是 99.95% 前提；**13 副本需 ≥5 台节点**（每台最多容 3 个 2C 副本）；HPA 缩容不经 Eviction API ⇒ PDB 拦不住自动缩容
A31: 28 | B31: 工作负载 | C31: canary Deployment | D31: — | E31: 1 | F31: new-api-canary | G31: 马尼拉 | H31: replicas=1；独立 Service 与 Ingress；canary-weight 5→20→50→100 —— ✅ 2026-10-12 已下发，V1–V6 全过（权重 5 生效且可归零） | I31: 26 | J31: GitOps | K31: D3 | L31: 人员B | M31: 灰度失败可秒级归零
A32: 29 | B32: 工作负载 | C32: Namespace / ConfigMap / Secret | D32: — | E32: 1 | F32: namespace: new-api | G32: 马尼拉 | H32: 见 impl_deploy.md 7.4.1；**密钥改手工 Opaque Secret 注入（不使用 KMS/RRSA/ExternalSecret）**；ConfigMap 默认 SQL_MAX_OPEN_CONNS=100，备站 Pod 用 env 覆盖为 10（env > envFrom 已实测） | I32: 20,11 | J32: GitOps | K32: D2 | L32: 人员B | M32: SESSION_SECRET 必须全区域一致；轮换须走双密钥过渡（见动作 #55）
A33: 30 | B33: 计算 | C33: PgBouncer（RDS 内置托管池） | D33: RDS PostgreSQL 内置托管 PgBouncer（实例上已启用，无自建部署） | E33: 1 | F33: —（托管形态，无独立资源） | G33: 马尼拉 | H33: 实测参数：max_client_conn=2000 / default_pool_size=50 / pool_mode=transaction / query_wait_timeout=120；内网串与公网串均监听 6432；master 迁移路径直连不走池 | I33: 14,15 | J33: GitOps | K33: D2 | L33: 人员B | M33: F10 已撤销自建口径；I-1 仅在 CK 日志库分支成立（13×100 + 20×10 = 1500 ≤ 2000 ✅）；「池化是切流硬性前置」不变
A34: 31 | B34: 网络 | C34: 节点池自动伸缩（ACK 托管弹性组件 ack-goatscaler） | D34: ACK 托管侧组件（版本随 ACK） | E34: 1 | F34: —（无独立资源；状态在 cm/kube-system/autoscaler-meta） | G34: 马尼拉 | H34: 节点池 np-mnl-app enable=true min 4 / max 8（按量 PostPaid，配额 64/64）；scan_interval 60s / expander least-waste / utilization_threshold 0.5 / unneeded_duration 10m / cool_down_duration 10m / **scale_down_enabled true** | I34: 11 | J34: GitOps | K34: D4 | L34: 人员A | M34: 组件存在性已证（lease 续租与节点 date -u 同秒）；**「能自动扩出节点」从未被验证** ⇒ 任务 42 验收未做；scale_down_enabled=true 与 HPA 缩容构成双层缩容风险
A35: 32 | B35: 接入 | C35: 证书部署与 SNI 校验 | D35: — | E35: 1 | F35: — | G35: 马尼拉 | H35: 证书部署至 ALB / WAF / DCDN；ALB 层启用 SNI 与域名校验 —— ✅ 2026-10-12：证书 606823-ap-southeast-1 已部署至两地 ALB 443 并通过链校验/SNI（⏸ 2026-10-12 F15：WAF 本轮不采购、DCDN 未启用 ⇒ 本卡部署对象只剩 ALB） | I35: 7,8,9 | J35: 控制台 | K35: D5 | L35: 人员A | M35: 修正原方案「D1 部署证书但 ALB/WAF 尚未创建」的时序错误
A36: 33 | B36: 计算 | C36: staging / perf 环境 | D36: ACK 命名空间 + 2 × g8i.xlarge（按需） | E36: 1 | F36: ns: new-api-staging / new-api-perf | G36: 马尼拉 | H36: 集成与三数据库矩阵验证、压测矩阵承载；使用主站 RDS 的逻辑隔离 schema（不新建实例，不构成对「新加坡不部署 RDS」红线的例外） | I36: 10 | J36: GitOps | K36: D3 | L36: 人员A | M36: 修复原方案「#33 压测无环境可跑」；impl_deploy.md 7.9 环境矩阵的前置
... A38: 35 | B38: 数据 | C38: 连接数预算与参数组 | D38: — | E38: 1 | F38: — | G38: 马尼拉 | H38: SQL_MAX_OPEN_CONNS=100（一个值同时管主库与日志库）/ RDS max_connections=800 ⇒ 预算上限 640 / 托管池 max_client_conn=2000；核算式：(主站 conns × 实例数) + (备 region conns × 实例数) ≤ max_connections × 0.8 | I38: 4 | J38: 控制台 | K38: D2 | L38: 人员B | M38: 落地任务 #4「参数组」的验收项；扩容后避免打爆 PG。**代码里没有 LOG_SQL_MAX_OPEN_CONNS**（主库与日志库读同一组变量）⇒ 不存在「只降日志库」的路径
A39: 36 | B39: 网络 | C39: 出口带宽规格 | D39: NAT 网关 ≥ 200 Mbps；EIP 峰值 ≥ 100 Mbps | E39: — | F39: — | G39: 马尼拉 | H39: 按 1,000 并发 ≈ 40 Mbps 估算并留 burst 余量；ALB LCU 上限一并确认 | I39: 4 | J39: 控制台 | K39: D1 | L39: 人员A | M39: 流式网关硬瓶颈（impl_deploy.md 8.5）
A40: 37 | B40: 观测 | C40: Grafana 服务 / 工作区 | D40: 按量 | E40: 1 | F40: grafana-newapi-mnl | G40: 马尼拉 | H40: SLO 与错误预算看板载体，对接 ARMS Prometheus 数据源 | I40: 22 | J40: 控制台 | K40: D4 | L40: 人员A | M40: impl_deploy.md 7.8 观测栈要求
A41: 38 | B41: 安全 | C41: 运维访问面 | D41: 堡垒机 / VPN + ACK 私网端点 | E41: 1 | F41: — | G41: 马尼拉 | H41: kubeconfig 分发 + RAM→RBAC 映射 + API Server 私网端点（或 ACL 白名单）+ 生产变更审批路径 | I41: 10 | J41: 控制台 | K41: D2 | L41: 人员A | M41: ACK Pro 默认公网端点属高风险面，须关闭或加 ACL；**2026-10-05 已实测 newapi-master PUBLIC→PRIVATE，双 SA 门禁复验通过**
A42: 39 | B42: 观测 | C42: 成本看板与预算告警 | D42: 按量 | E42: 1 | F42: — | G42: 马尼拉 | H42: 成本标签 site / project / env；月度预算告警阈值 80%；覆盖出站流量、ALB LCU、跨区公网读写、WAF 请求数、DCDN 流量、GA（如启用） | I42: 5 | J42: 控制台 | K42: D5 | L42: 人员A | M42: 原方案无成本量化，主要变量未落入表格；**节点单价按实况整机（含系统盘 100G ESSD + 数据盘 300G ESSD PL1）取：g9ae 包月 288.82 / 按量 0.51848 USD·h（4 台按量 ≈1513.96 USD/月）**

Sheet 资源清单-新加坡
A1: 备 region 资源清单 · ap-southeast-1（新加坡，仅承载菲律宾备用负载）
A3: 序号 | B3: 层 | C3: 资源 / 产品 | D3: 规格与版本 | E3: 数量 | F3: 命名规范 | G3: 地域 / 可用区 | H3: 关键配置 | I3: 前置依赖 | J3: 申请方式 | K3: 落地日 | L3: 负责 | M3: 备注
A4: 1 | B4: 网络 | C4: VPC | D4: 10.1.0.0/16 | E4: 1 | F4: vpc-newapi-sg-prod | G4: ap-southeast-1 | H4: 独立 VPC；不部署任何数据库实例 | I4: — | J4: 控制台/IaC | K4: D1 | L4: 人员A | M4: 网段与马尼拉不重叠
A5: 2 | B5: 网络 | C5: vSwitch | D5: 2 × /24 + 8 × /20 | E5: 10 | F5: vsw-sg-pub-a/b、vsw-sg-app-a/b/c/d、vsw-sg-data-a/b/c/d | G5: 跨 4 个可用区（1a/1b/1c/1d） | H5: 公共子网承载 ALB 与 NAT；私有子网承载 Pod | I5: 1 | J5: 控制台/IaC | K5: D1 | L5: 人员A | M5: 至少 2 个可用区（2026-10-08 扩为 4：app/data 各 +c/d）
A6: 3 | B6: 网络 | C6: NAT 网关 + EIP 池 | D6: ≥ 4 个 EIP | E6: 4 | F6: nat-sg-prod / eip-sg-upstream-01..04 | G6: 多可用区 | H6: 固定 EIP 两用：① 上游出口白名单；② 马尼拉 RDS 公网白名单来源 | I6: 1 | J6: 控制台/IaC | K6: D1 | L6: 人员A | M6: 关键：这批 EIP 必须加入马尼拉 RDS 白名单，禁止 0.0.0.0/0
A7: 4 | B7: 接入 | C7: ALB | D7: 标准版 II | E7: 1 | F7: alb-newapi-sg | G7: 跨 2 个可用区 | H7: 实况：**只有 HTTP:80 一个监听**（443 待 G5）；idleTimeout 60s + requestTimeout 180s；⚠ sg 侧两个服务器组挂同一批 ENI、pri=2 无 host 条件（任意 Host 进业务组）⇒ 属任务 25/47 收口项 | I7: 3,17(前置) | J7: 控制台/IaC | K7: D4 | L7: 人员A | M7: GTM 接管时直接解析到该 ALB
A8: 5 | B8: 接入 | C8: WAF 3.0 | D8: ⏸ 2026-10-12 裁定（F15）：本轮**不采购**（与马尼拉同口径，暂缓）；备站接管后同样无 L7 防护，属知情接受风险（任务 25 坑 2） | E8: 1 | F8: waf-newapi-sg | G8: 新加坡 | H8: 接管时承接 www.likha.hk 流量（备站另有公网入口 sg.likha.hk，2026-10-09 裁定新增，不进 GTM 池）；规则与马尼拉保持一致；⏸ 2026-10-12 F15：两地均不接 WAF ⇒ 接管后无「WAF 规则一致性」校验项，改为两地 ALB 监听/Ingress 规则 diff（任务 34） | I8: 4 | J8: 控制台 | K8: D4 | L8: 人员A | M8: 规则差异会导致切换后行为不一致
A9: 6 | B9: 接入 | C9: ACR 企业版（新加坡） | D9: 单地域马尼拉（不建独立 ACR） | E9: 1 | F9: acr-newapi-sg | G9: ap-southeast-1 | H9: **F8：镜像源改单地域马尼拉**；新加坡不建独立 ACR，跨区用马尼拉 ACR 公网域名拉取（sg 节点解析不了 -vpc 内网域名） | I9: 12(前置) | J9: 控制台 | K9: D1 | L9: 人员B | M9: ACR EE 端点只接受本地域 VPC 绑定 ⇒ 跨区内网拉镜像不可行；Pull 凭据挂在 SA/new-api-app
A10: 7 | B10: 计算 | C10: ACK Pro 托管版 | D10: 控制面 SLA 99.95% | E10: 1 | F10: ack-newapi-sg | G10: 多可用区 | H10: 与马尼拉同构；本期仅承载 PH 备（泰国备为二期、不共用本集群）。二期若让泰国备复用该集群（独立 Deployment），须重算节点池上限并重新申请配额 | I10: 1 | J10: 控制台 | K10: D3 | L10: 人员A | M10: 不同站点备负载必须互相隔离
A11: 8 | B11: 计算 | C11: ECS 节点池 | D11: ecs.g9i.2xlarge（8C32G，**首选**）；实况 2 台为**混型**：ecs.g8ine.2xlarge + ecs.g9ae.2xlarge | E11: ≥ 2 | F11: ecs-sg-node-01..02 | G11: 跨 2 个可用区 | H11: PH 备常态 2 副本（本期唯一工作负载，不含泰国备）；节点池自动伸缩 min 2 / **max 12**（实况配额 96 vCPU）。按接管 20 副本折算：20 × request 2 vCPU = 40 vCPU，÷ (7.9 × 0.8 = 6.32) ≈ 6.3 → 7 节点（容量下限 8 节点 / 64 vCPU）；冷备形态会拉长 RTO | I11: 7 | J11: 控制台 | K11: D3 | L11: 人员A | M11: 冷备会牺牲 RTO（秒级 → 分钟级）；接管容量验收见 M4
A12: 9 | B12: 数据 | C12: RDS PostgreSQL | D12: — | E12: 0 | F12: — | G12: 新加坡 | H12: 【不部署】备 region 直接使用马尼拉 RDS 的公网地址 | I12: — | J12: — | K12: — | L12: 人员B | M12: 红线：禁止本地库、只读副本、DTS 双向链路
A13: 10 | B13: 数据 | C13: RDS 公网白名单 | D13: — | E13: 1 | F13: — | G13: 马尼拉 RDS | H13: 仅加入新加坡 NAT EIP；仅开放 5432；应用侧 sslmode=verify-full + RDS CA 校验 | I13: 3,14(马尼拉) | J13: 控制台 | K13: D2 | L13: 人员B | M13: 连接串不得出现 sslmode=disable / require
A14: 11 | B14: 缓存 | C14: Tair（Redis 兼容） | D14: 主备版 4 GB | E14: 1 | F14: tair-sg-newapi | G14: 多可用区 | H14: 备 region 本地缓存与限流；不跨区访问马尼拉 Tair | I14: 1 | J14: 控制台 | K14: D4 | L14: 人员B | M14: 跨区缓存会放大延迟与故障面
A15: 12 | B15: 日志 | C15: 云数据库 ClickHouse | D15: 【不部署】并入马尼拉 ClickHouse 企业版单 AZ（F9） | E15: 1 | F15: ck-sg-newapi | G15: 新加坡 | H15: **【不部署】F9 修订：备 region 日志库并入马尼拉 ClickHouse 企业版单 AZ**，不再购买新加坡 CK | I15: 1 | J15: 控制台 | K15: D4 | L15: 人员B | M15: 原「备 region 本地日志库」口径已作废（F9）；2026-10-09 复核更正：马尼拉 CK 已有 PUBLIC 端点（43.118.97.47）+ 白名单组 sg_eip 含新加坡 4 个 SNAT EIP，备站跨区写已实测通过（任务 29 执行记录 6；与「资源清单-马尼拉」H21 一致）⇒ 原「待裁定」闭合
A16: 13 | B16: 存储 | C16: OSS Bucket | D16: 标准 + 低频生命周期 | E16: 1 | F16: oss-newapi-sg | G16: 新加坡 | H16: 版本控制 + 90 天转归档 | I16: 1 | J16: 控制台 | K16: D1 | L16: 人员B | M16: DCDN 回源可指向本 bucket
A17: 14 | B17: 安全 | C17: 安全组 | D17: — | E17: — | F17: sg-sg-alb / sg-sg-app | G17: 新加坡 | H17: alb 入向 80,443（443 已于 2026-10-12 落地并验收：lsn-iqn5i233mvv7eu4u6w + 证书 Associated）；app 入向 3000 仅来自 alb-sg；app 出向允许访问马尼拉 RDS **公网 6432（经托管池，2026-09-29 裁定② 乙路）**；跨区 TLS 用 verify-full + sslrootcert（Secret rds-ca-apse6 挂 /etc/ssl/rds） | I17: 2,10 | J17: 控制台 | K17: D3 | L17: 人员A | M17: 出向按目的地址精确放行
A18: 15 | B18: 工作负载 | C18: PH 备 Deployment | D18: — | E18: 1 | F18: new-api-ph-standby | G18: 跨 2 个可用区 | H18: replicas=2（常态，热备）；NODE_TYPE=slave；track=standby；site=ph；**Pod 内 SQL_MAX_OPEN_CONNS=10 / SQL_MAX_IDLE_CONNS=5（由 Deployment env 覆盖 CM 的 100/50，实测 env > envFrom）**；HPA min 2 / max **20** | I18: 7,11 | J18: GitOps | K18: D3 | L18: 人员B | M18: 必须固定 slave，避免与马尼拉 master 并发迁移同一 schema；HPA 上限 20 = 主站 maxReplicas 13 × 1.5（19.5 上取整）
A19: 16 | B19: 工作负载 | C19: 备 region Secret | D19: — | E19: 1 | F19: new-api-secret-sg-ph | G19: 新加坡 | H19: SQL_DSN 指向马尼拉 RDS 公网地址；SESSION_SECRET 与主站点完全一致 | I19: 20(马尼拉) | J19: GitOps | K19: D3 | L19: 人员B | M19: 同 SESSION_SECRET 保证接管瞬间会话与令牌不失效；轮换走双密钥过渡
A20: 17 | B20: 观测 | C20: SLS / ARMS 接入 | D20: 按量 | E20: 1 | F20: sls-newapi-sg / arms-newapi-sg | G20: 新加坡 | H20: 与应用同构采集；备 region 日志单独 LogStore | I20: 7 | J20: 控制台 | K20: D4 | L20: 人员A | M20: 告警通道复用主站点值班表
A21: 18 | B21: 观测 | C21: 备 region 链路拨测 | D21: 按量 | E21: 1 | F21: — | G21: 新加坡 → 马尼拉 | H21: 对马尼拉 RDS 公网地址做 TCP 拨测：RTT、连接失败率、连接数占比 | I21: 10 | J21: 控制台 | K21: D4 | L21: 人员B | M21: 链路不健康时必须阻止 GTM 接管到备 region
A22: 19 | B22: 计算 | C22: 节点池自动伸缩（ACK 托管弹性组件 ack-goatscaler） | D22: — | E22: 1 | F22: —（无独立资源；状态在 cm/kube-system/autoscaler-meta） | G22: 新加坡 | H22: min 2 / max 12（实况配额 96 vCPU）；支撑备 region 20 副本接管（40 vCPU 需求 + ≥20% 系统组件余量 ⇒ 容量下限 8 节点 / 64 vCPU） | I22: 7 | J22: GitOps | K22: D4 | L22: 人员A | M22: 实批按量配额 96 vCPU（见账号与域名申请 #7）；本期不含泰国备，故未按双站点接管的 96 vCPU 申请
A23: 20 | B23: 工作负载 | C23: PH 备 HPA | D23: — | E23: 1 | F23: hpa-new-api-ph-standby | G23: 新加坡 | H23: min 2 / max **20**；Pod request 2 vCPU；接管前先扩容再切流（扩容 → Ready → 加入 GTM） | I23: 18,19 | J23: GitOps | K23: D5 | L23: 人员B | M23: 满足「单站点全量接管 = 被接管站点 maxReplicas **13** × 1.5 = 19.5 → **20 副本**」
A25: 重申红线： 新加坡【不部署 RDS PostgreSQL】（含只读副本与 DTS）。备 region 仅通过公网 TLS（verify-full + IP 白名单）读写马尼拉主库，仅故障接管时生效，不做双写。staging / perf 环境位于马尼拉主站点（主站 RDS 的逻辑隔离 schema），不构成对本红线的例外。 【容量要求】备 region 可扩容上限 = 被接管站点 maxReplicas 13 × 1.5 = 19.5 → **20 副本**（常备 2 副本 + HPA 2–20 + 节点池自动伸缩 2–12，实况配额 96 vCPU）。 【分期口径】本期新加坡仅承载 PH 备、不含泰国备；二期引入 TH 备时须重算节点池上限（两地同时接管需 48 副本 / 96 vCPU，含 ≥20% 余量即 ≥16 节点 / 128 vCPU）并重新申请配额。

Sheet 网络与安全规划
A1: 网络、安全组、EIP 与凭据规划（v2.1 修订版）
A3: 站点 | B3: 地域 / 可用区 | C3: 资源 | D3: 规划值 | E3: 用途 / 说明 | F3: 备注
A4: 马尼拉 | B4: ap-southeast-6 | C4: VPC CIDR | D4: vpc-newapi-mnl-prod 10.0.0.0/16 | E4: 菲律宾主站点网络 | F4: 与新加坡不重叠
A5: 马尼拉 | B5: 可用区 A | C5: vSwitch | D5: vsw-mnl-pub-a 10.0.0.0/24 | E5: ALB 公共子网 | F5: —
A6: 马尼拉 | B6: 可用区 B | C6: vSwitch | D6: vsw-mnl-pub-b 10.0.1.0/24 | E6: ALB 公共子网 | F6: 多可用区
A7: 马尼拉 | B7: 可用区 A | C7: vSwitch | D7: vsw-mnl-app-a 10.0.16.0/20 | E7: ACK Pod 私有子网 | F7: —
A8: 马尼拉 | B8: 可用区 B | C8: vSwitch | D8: vsw-mnl-app-b 10.0.32.0/20 | E8: ACK Pod 私有子网 | F8: —
A9: 马尼拉 | B9: 可用区 A | C9: vSwitch | D9: vsw-mnl-data-a 10.0.48.0/20 | E9: RDS / Tair / ClickHouse | F9: 数据库不暴露公网子网
A10: 马尼拉 | B10: 可用区 B | C10: vSwitch | D10: vsw-mnl-data-b 10.0.64.0/20 | E10: RDS 备实例 | F10: 主备跨可用区
A11: 新加坡 | B11: ap-southeast-1 | C11: VPC CIDR | D11: vpc-newapi-sg-prod 10.1.0.0/16 | E11: 备 region 网络（数据库段已按偏移预留、未挂实例） | F11: 与马尼拉不重叠
A12: 新加坡 | B12: 可用区 A | C12: vSwitch | D12: vsw-sg-pub-a 10.1.0.0/24 | E12: ALB 与 NAT | F12: —；实测 vsw-t4ncxa4gqgamhl0o8e6yq / ap-southeast-1a / 可用 IP 251
A13: 新加坡 | B13: 可用区 B | C13: vSwitch | D13: vsw-sg-pub-b 10.1.1.0/24 | E13: ALB 公共子网（第 2 可用区） | F13: ALB 需跨 2 个可用区，原 v2.0 表缺失本行（已补）；实测 vsw-t4nhtsfk2z79e1ggvlhdz / ap-southeast-1b / 可用 IP 252
A14: 新加坡 | B14: 可用区 A | C14: vSwitch | D14: vsw-sg-app-a 10.1.16.0/20 | E14: PH 备 Pod | F14: —；实测 vsw-t4nbvsnvo4z52sumr9sck / ap-southeast-1a / 可用 IP 4073（已用 19，节点与 Pod 在此段）
... A29: 雅加达 dev | B29: 可用区 5b | C29: vSwitch | D29: vsw-jkt-dev-data-5b 10.2.64.0/20 | E29: RDS / Tair 私有子网 | F29: 多可用区/备实例候选段，主备跨 AZ 时用；与马尼拉 vsw-mnl-data-b 同槽。偏移对齐重建：vsw-k1auat3gn6iagfg7by4sz
A30: EIP 规划（本次出口直出上游，不启用 GA；白名单 = 下列 8 个 EIP）
A31: 站点 | B31: 用途 | C31: 数量 | D31: 绑定对象 | E31: 说明 | F31: 备注
A32: 马尼拉 | B32: 上游出口白名单池 | C32: 4 | D32: NAT 网关 | E32: 提交给 OpenAI / Anthropic / Google / Azure / AWS 等供应商做 IP 白名单（马尼拉 4 个 + 新加坡 4 个，共 8 个，须逐一确认生效） | F32: 同一池用于上游白名单；本次不启用 GA（GA 为二期可选优化）
A33: 马尼拉 | B33: ALB 公网地址 | C33: 1 | D33: ALB | E33: 由 ALB 自动分配，用于 GTM 地址池与 DNS 解析 | F33: —
A34: 新加坡 | B34: 上游出口 + RDS 白名单池 | C34: 4 | D34: NAT 网关 | E34: 既用于供应商白名单，也必须加入马尼拉 RDS 公网白名单 | F34: 仅放行该 EIP，禁止 0.0.0.0/0
A35: 雅加达 dev | B35: dev 出网（跨区拉镜像 / 上游 mock） | C35: 1（已建） | D35: NAT 网关 + EIP | E35: 已建成：NAT 网关 ngw-k1aij9gqb72y38kl31vd2（Enhanced，落 pub-5a vsw-k1at4vt7fg8v4umkh9lg3）+ EIP eip-k1ans4dqvvci8x4jx1fx3 = 147.139.170.11（5Mbps PayByTraffic）；SNAT 条目 snat-k1acb22kut2qkwgdx4iub 覆盖 10.2.0.0/16；默认路由 rte-k1akjm3rkrdd62p55brnn 0.0.0.0/0→NatGateway 由系统随 NAT 自动下发。节点内实测出网公网 IP 即该 EIP。 | F35: 禁止并入生产 8 个 EIP 的上游 / RDS 白名单池。NAT 上线使 10.2.0.0/16 首次获得公网可达性，生产 RDS 公网端点由「路由不可达」变为「仅靠安全组拦截」，故已把 43.118.96.65/32 的出向规则由 drop TCP 5432 收紧为 drop ALL（见下方安全组段）。
A37: 安全组规则（最小开放原则；对端 CIDR 收敛。**⚠ 2026-10-06 定稿例外：ALB 入向保持 0.0.0.0/0 :80,443 不收敛** —— WAF 3.0 走云原生 SDK 接入而非透明代理，未匹配 Host 由 Ingress 规则/catchall 兜底，直连 ALB 公网 IP 属已裁定接受项（任务 47）。⚠ 2026-10-12 F15：WAF 本轮不采购 ⇒ 该例外失去前置 L7 防护层，实际兜底只剩 alb-access 审计 + Ingress Host/catchall + 应用 360/180s 限流；是否改用 ALB ACL 收敛重开为待裁定（任务 47 追加登记 ⑥）
A38: 站点 | B38: 安全组 | C38: 方向 | D38: 协议 / 端口 | E38: 源 / 目的 | F38: 说明
A39: 马尼拉 | B39: sg-mnl-alb | C39: 入 | D39: TCP 443 / 80 | E39: 实况（2026-10-06 裁定）：**保持 0.0.0.0/0 :80,443 不收敛**（WAF 3.0 走云原生接入，待任务 20）；原「仅放行 WAF/DCDN 回源段」的收敛方案不执行 | F39: 未匹配 Host 已由 Ingress/new-api-catchall-404 兜底 404（任务 47）；80 仅用于 301 跳转 HTTPS
A40: 马尼拉 | B40: sg-mnl-app | C40: 入 | D40: TCP 3000 | E40: sg-mnl-alb | F40: 仅 ALB 可访问 Pod，禁止内网其他来源
A41: 马尼拉 | B41: sg-mnl-app | C41: 出 | D41: TCP 5432 / 6379 / 9000 | E41: sg-mnl-db | F41: 访问 RDS、Tair、ClickHouse
A42: 马尼拉 | B42: sg-mnl-app | C42: 出 | D42: TCP 443 | E42: 0.0.0.0/0 经 NAT 网关出网 | F42: 企业私有子网访问外部 AI 供应商的必要放通，风险由目的地址与出向限速约束
A43: 马尼拉 | B43: sg-mnl-db | C43: 入 | D43: TCP 5432 | E43: sg-mnl-app、10.1.0.0/16 | F43: 主站点走内网；备 region 跨 VPC 无法以安全组表达，实际生效源由 RDS 公网白名单二次收敛为新加坡 NAT EIP
A44: 马尼拉 | B44: sg-mnl-alb-edge | C44: 入 | D44: TCP 22 / 443 | E44: 企业办公出口 IP 段 | F44: 堡垒机 / VPN 入口（运维访问面）；禁止 0.0.0.0/0
A45: 马尼拉 | B45: sg-mnl-ack-api | C45: 入 | D45: TCP 6443 | E45: 企业办公出口 IP 段 | F45: ACK API Server：关闭公网端点或加 ACL 白名单
A46: 新加坡 | B46: sg-sg-alb | C46: 入 | D46: TCP 443 / 80 | E46: 实况（2026-10-06 裁定，与马尼拉同口径）：保持 0.0.0.0/0 :80,443 不收敛；2026-10-12 两地 ALB 443 已落地；⚠ 2026-10-12 F15：任务 20 裁定不执行 ⇒ 不收敛再无 WAF 缓解（原括注「WAF 3.0 云原生 SDK 接入，待任务 20」作废），与主站同列待裁定 | F46: GTM 接管时的备 region 入口；与主站点同口径不收敛（2026-10-06 裁定；原「禁止 0.0.0.0/0」作废）
A47: 新加坡 | B47: sg-sg-app | C47: 入 | D47: TCP 3000 | E47: sg-sg-alb | F47: 与主站点一致
A48: 新加坡 | B48: sg-sg-app | C48: 出 | D48: TCP 5432 | E48: 马尼拉 RDS 公网 IP /32，**端口 6432（经托管池）** | F48: sg-sg-app 实测为 normal 类型、出向默认放行 ⇒ 无需额外写规则；仅接管期写入，强制 TLS verify-full
A49: 新加坡 | B49: sg-sg-app | C49: 出 | D49: TCP 443 | E49: 0.0.0.0/0 经 NAT 网关出网 | F49: 接管期调用上游 AI 供应商
... A55: 雅加达 dev | B55: sg-jkt-dev-app | C55: 入 | D55: 无自定义规则（保持默认） | E55: — | F55: 入向仅组内互通；生产侧安全组、生产 RDS 白名单、生产 ACR EE 公网 ACL 均未因本次改动（见 jakarta_dev_ledger §3）
A57: 凭据与密钥（2026-10-05 裁定不使用 KMS：手工 Opaque Secret 注入，禁止落库落 Git）
A58: 凭据 | B58: 载体 | C58: 使用方 | D58: 轮换周期 | E58: 说明 | F58: 备注
A59: SQL_DSN | B59: K8s Opaque Secret（手工注入） | C59: 马尼拉 / 新加坡备应用 | D59: 90 天 | E59: 含数据库账号密码；备 region 使用公网地址 + verify-full（SG 侧已切 verify-full + sslrootcert=/etc/ssl/rds/ca.crt） | F59: 轮换需两站点同步；经 PgBouncer 时 DSN 指向池地址
A60: REDIS_CONN_STRING | B60: K8s Opaque Secret（手工注入） | C60: 马尼拉 / 新加坡备应用 | D60: 90 天 | E60: Tair 连接串 | F60: 各站点使用各自实例
A61: SESSION_SECRET | B61: K8s Opaque Secret（手工注入） | C61: 全部站点 | D61: 180 天（双密钥过渡） | E61: 必须全区域全实例一致 | F61: 不一致会导致切换后会话全部失效；必须支持新旧密钥并存过渡，否则轮换即全量会话失效（任务 #55）
A62: RDS CA 证书（已落 Secret rds-ca-apse6） | B62: K8s Secret rds-ca-apse6 → 挂载 /etc/ssl/rds/ca.crt | C62: 新加坡备 region | D62: 随证书更新 | E62: 用于 sslmode=verify-full 校验 | F62: 禁止使用 require/disable
...

Sheet 落地计划
A1: 5 天冲刺排期 · 每天 3 个工作段（S1 上午 09:00–13:00 / S2 下午 14:00–18:00 / S3 晚间 19:00–23:00，晚间段为加班段）· 单人每段上限 4 人时。（⚠ 现行工期口径 = 1 人 × 4 天 / 8 个执行窗口，见指南 §0.2–§0.4；本表 5 天 / 2 人 / 15 段为 v2.3 历史口径，保留供追溯）
A2: 天 / 时段 | J2: D1 | M2: D2 | P2: D3 | S2: D4 | V2: D5 | AB2: 验收标准 / 状态 / 每时段投入
A3: 天 | B3: 序号 | C3: 任务 / 交付物 | D3: 负责 | E3: 前置依赖 | F3: 工期(人时) | G3: 起始时段 | H3: 完成时段 | I3: 日期 | J3: S1 | K3: S2 | L3: S3 | M3: S4 | N3: S5 | O3: S6 | P3: S7 | Q3: S8 | R3: S9 | S3: S10 | T3: S11 | U3: S12 | V3: S13 | W3: S14 | X3: S15 | AB3: 验收标准 | AC3: 状态 | AD3: 每时段投入(人时)
A4: D1 | B4: 1 | C4: 账号/实名/配额/支付最终确认与补件（门禁 G0 收口） | D4: 人员A | E4: G0（G1–G7/G9 已闭环） | F4: 2 | G4: 2 | H4: 2 | I4: =说明与总览!$B$21+VALUE(MID($A4,2,1))-1 | J4: =IF(AND($G4<=1,$H4>=1),"■■","") | K4: =IF(AND($G4<=2,$H4>=2),"■■","") | L4: =IF(AND($G4<=3,$H4>=3),"■■","") | M4: =IF(AND($G4<=4,$H4>=4),"■■","") | N4: =IF(AND($G4<=5,$H4>=5),"■■","") | O4: =IF(AND($G4<=6,$H4>=6),"■■","") | P4: =IF(AND($G4<=7,$H4>=7),"■■","") | Q4: =IF(AND($G4<=8,$H4>=8),"■■","") | R4: =IF(AND($G4<=9,$H4>=9),"■■","") | S4: =IF(AND($G4<=10,$H4>=10),"■■","") | T4: =IF(AND($G4<=11,$H4>=11),"■■","") | U4: =IF(AND($G4<=12,$H4>=12),"■■","") | V4: =IF(AND($G4<=13,$H4>=13),"■■","") | W4: =IF(AND($G4<=14,$H4>=14),"■■","") | X4: =IF(AND($G4<=15,$H4>=15),"■■","") | AB4: G0 门禁全部通过，无遗留待批复项 | AC4: 部分交付（§0.7 G0：G1/G2/G3/G4/G5/G10/G12 已闭环，G5 于 2026-10-12 签发；G6/G7/G8/G11/G13 仍待闭环） | AD4: =IF($H4<$G4,0,$F4/($H4-$G4+1))
A5: D1 | B5: 2 | C5: 域名解析记录与 NS 生效复核 | D5: 人员B | E5: G4,G5 | F5: 1 | G5: 3 | H5: 3 | I5: =说明与总览!$B$21+VALUE(MID($A5,2,1))-1 | J5: =IF(AND($G5<=1,$H5>=1),"■■","") | K5: =IF(AND($G5<=2,$H5>=2),"■■","") | L5: =IF(AND($G5<=3,$H5>=3),"■■","") | M5: =IF(AND($G5<=4,$H5>=4),"■■","") | N5: =IF(AND($G5<=5,$H5>=5),"■■","") | O5: =IF(AND($G5<=6,$H5>=6),"■■","") | P5: =IF(AND($G5<=7,$H5>=7),"■■","") | Q5: =IF(AND($G5<=8,$H5>=8),"■■","") | R5: =IF(AND($G5<=9,$H5>=9),"■■","") | S5: =IF(AND($G5<=10,$H5>=10),"■■","") | T5: =IF(AND($G5<=11,$H5>=11),"■■","") | U5: =IF(AND($G5<=12,$H5>=12),"■■","") | V5: =IF(AND($G5<=13,$H5>=13),"■■","") | W5: =IF(AND($G5<=14,$H5>=14),"■■","") | X5: =IF(AND($G5<=15,$H5>=15),"■■","") | AB5: dig 权威解析生效，解析记录无冲突 | AC5: 部分交付（G4 NS 已闭环、www.likha.hk 解析在用；ops.likha.hk 现网无记录，见指南 §2 域名表） | AD5: =IF($H5<$G5,0,$F5/($H5-$G5+1))
A6: D2 | B6: 3 | C6: 证书就绪与部署预置（配置模板 / 手工保管私钥 / 到期告警） | D6: 人员A | E6: G6 | F6: 1 | G6: 4 | H6: 4 | I6: =说明与总览!$B$21+VALUE(MID($A6,2,1))-1 | J6: =IF(AND($G6<=1,$H6>=1),"■■","") | K6: =IF(AND($G6<=2,$H6>=2),"■■","") | L6: =IF(AND($G6<=3,$H6>=3),"■■","") | M6: =IF(AND($G6<=4,$H6>=4),"■■","") | N6: =IF(AND($G6<=5,$H6>=5),"■■","") | O6: =IF(AND($G6<=6,$H6>=6),"■■","") | P6: =IF(AND($G6<=7,$H6>=7),"■■","") | Q6: =IF(AND($G6<=8,$H6>=8),"■■","") | R6: =IF(AND($G6<=9,$H6>=9),"■■","") | S6: =IF(AND($G6<=10,$H6>=10),"■■","") | T6: =IF(AND($G6<=11,$H6>=11),"■■","") | U6: =IF(AND($G6<=12,$H6>=12),"■■","") | V6: =IF(AND($G6<=13,$H6>=13),"■■","") | W6: =IF(AND($G6<=14,$H6>=14),"■■","") | X6: =IF(AND($G6<=15,$H6>=15),"■■","") | AB6: 证书已签发、私钥手工保管（不使用 KMS）、30 天到期告警生效 | AC6: 已完成（2026-10-12 实测 4/4 交付，本卡闭合）：① 私钥+全链入 /root/.deploy_secrets/TLS_WILDCARD_{CRT,KEY}（-rw------- root root 6075/1675、leaf 在前、链 3 张、-modulus md5 两侧同为 df343b79775… ⇒ 配对 PASS，执行器 deploy/logs/tls_store_20261012.sh）；② notAfter=2027-04-28 ≥ 今+30 天、SAN 含 *.likha.hk 与 likha.hk、openssl verify OK、CAS CertificateStatus=issued（CertId=606823）；③ 到期告警：控制台由负责人自配（⚠ 无 API 可取证，证据=负责人确认，配置页截图仍欠），另经授权开实例级自动托管续签 UpdateInstance --AutoReissue enable，GetInstanceDetail 与 ListInstances 双路回读均为 enable（写前 disable）；④ 模板落地 deploy/cert/targets.yaml（含现场回读的 ALB/监听 ID）。★ 长期风险如实登记：AutoReissueCount 仍 0、ListTrusteeOrder NotFound、ListDeploymentJob 与 ListCloudResources(alb) 全空 ⇒ ALB 直接绑 CertIdentifier、无 CAS 部署联动 ⇒ 续签后须人工把新 CertId 换绑两地 HTTPS 监听（R1–R4 已写入 targets.yaml，2027-03-29 前执行）。⚠ 另：本轮调试用 bash -x 把私钥正文留在本机会话记录（无远端副本），负责人裁定按「接受」处置，2027-03 续签窗口自然换新；永久规则=处理私钥的脚本禁 -x。 | AD6: =IF($H6<$G6,0,$F6/($H6-$G6+1))
A7: D1 | B7: 4 | C7: 创建马尼拉 RDS PostgreSQL 高可用版（主备跨 AZ）+ 参数组 | D7: 人员B | E7: G2,G3 | F7: 2 | G7: 1 | H7: 1 | I7: =说明与总览!$B$21+VALUE(MID($A7,2,1))-1 | J7: =IF(AND($G7<=1,$H7>=1),"■■","") | K7: =IF(AND($G7<=2,$H7>=2),"■■","") | L7: =IF(AND($G7<=3,$H7>=3),"■■","") | M7: =IF(AND($G7<=4,$H7>=4),"■■","") | N7: =IF(AND($G7<=5,$H7>=5),"■■","") | O7: =IF(AND($G7<=6,$H7>=6),"■■","") | P7: =IF(AND($G7<=7,$H7>=7),"■■","") | Q7: =IF(AND($G7<=8,$H7>=8),"■■","") | R7: =IF(AND($G7<=9,$H7>=9),"■■","") | S7: =IF(AND($G7<=10,$H7>=10),"■■","") | T7: =IF(AND($G7<=11,$H7>=11),"■■","") | U7: =IF(AND($G7<=12,$H7>=12),"■■","") | V7: =IF(AND($G7<=13,$H7>=13),"■■","") | W7: =IF(AND($G7<=14,$H7>=14),"■■","") | X7: =IF(AND($G7<=15,$H7>=15),"■■","") | AB7: 实例可连、主备跨可用区、参数组生效 | AC7: 已完成 | AD7: =IF($H7<$G7,0,$F7/($H7-$G7+1))
A8: D1 | B8: 5 | C8: 创建马尼拉 VPC 与 4 组 vSwitch（跨 2 AZ） | D8: 人员A | E8: G1,G2 | F8: 4 | G8: 1 | H8: 1 | I8: =说明与总览!$B$21+VALUE(MID($A8,2,1))-1 | J8: =IF(AND($G8<=1,$H8>=1),"■■","") | K8: =IF(AND($G8<=2,$H8>=2),"■■","") | L8: =IF(AND($G8<=3,$H8>=3),"■■","") | M8: =IF(AND($G8<=4,$H8>=4),"■■","") | N8: =IF(AND($G8<=5,$H8>=5),"■■","") | O8: =IF(AND($G8<=6,$H8>=6),"■■","") | P8: =IF(AND($G8<=7,$H8>=7),"■■","") | Q8: =IF(AND($G8<=8,$H8>=8),"■■","") | R8: =IF(AND($G8<=9,$H8>=9),"■■","") | S8: =IF(AND($G8<=10,$H8>=10),"■■","") | T8: =IF(AND($G8<=11,$H8>=11),"■■","") | U8: =IF(AND($G8<=12,$H8>=12),"■■","") | V8: =IF(AND($G8<=13,$H8>=13),"■■","") | W8: =IF(AND($G8<=14,$H8>=14),"■■","") | X8: =IF(AND($G8<=15,$H8>=15),"■■","") | AB8: 网段与「网络与安全规划」完全一致 | AC8: 已完成 | AD8: =IF($H8<$G8,0,$F8/($H8-$G8+1))
A9: D1 | B9: 6 | C9: 创建马尼拉 NAT 网关与上游出口 EIP 池（含带宽规格） | D9: 人员A | E9: 5 | F9: 2 | G9: 2 | H9: 2 | I9: =说明与总览!$B$21+VALUE(MID($A9,2,1))-1 | J9: =IF(AND($G9<=1,$H9>=1),"■■","") | K9: =IF(AND($G9<=2,$H9>=2),"■■","") | L9: =IF(AND($G9<=3,$H9>=3),"■■","") | M9: =IF(AND($G9<=4,$H9>=4),"■■","") | N9: =IF(AND($G9<=5,$H9>=5),"■■","") | O9: =IF(AND($G9<=6,$H9>=6),"■■","") | P9: =IF(AND($G9<=7,$H9>=7),"■■","") | Q9: =IF(AND($G9<=8,$H9>=8),"■■","") | R9: =IF(AND($G9<=9,$H9>=9),"■■","") | S9: =IF(AND($G9<=10,$H9>=10),"■■","") | T9: =IF(AND($G9<=11,$H9>=11),"■■","") | U9: =IF(AND($G9<=12,$H9>=12),"■■","") | V9: =IF(AND($G9<=13,$H9>=13),"■■","") | W9: =IF(AND($G9<=14,$H9>=14),"■■","") | X9: =IF(AND($G9<=15,$H9>=15),"■■","") | AB9: EIP 固定可出网，NAT 带宽规格已确认 | AC9: 已完成 | AD9: =IF($H9<$G9,0,$F9/($H9-$G9+1))
A10: D1 | B10: 7 | C10: 创建 Tair 主备版实例 | D10: 人员B | E10: 4 | F10: 1 | G10: 3 | H10: 3 | I10: =说明与总览!$B$21+VALUE(MID($A10,2,1))-1 | J10: =IF(AND($G10<=1,$H10>=1),"■■","") | K10: =IF(AND($G10<=2,$H10>=2),"■■","") | L10: =IF(AND($G10<=3,$H10>=3),"■■","") | M10: =IF(AND($G10<=4,$H10>=4),"■■","") | N10: =IF(AND($G10<=5,$H10>=5),"■■","") | O10: =IF(AND($G10<=6,$H10>=6),"■■","") | P10: =IF(AND($G10<=7,$H10>=7),"■■","") | Q10: =IF(AND($G10<=8,$H10>=8),"■■","") | R10: =IF(AND($G10<=9,$H10>=9),"■■","") | S10: =IF(AND($G10<=10,$H10>=10),"■■","") | T10: =IF(AND($G10<=11,$H10>=11),"■■","") | U10: =IF(AND($G10<=12,$H10>=12),"■■","") | V10: =IF(AND($G10<=13,$H10>=13),"■■","") | W10: =IF(AND($G10<=14,$H10>=14),"■■","") | X10: =IF(AND($G10<=15,$H10>=15),"■■","") | AB10: 连接与 ACL 认证验证通过 | AC10: 已完成 | AD10: =IF($H10<$G10,0,$F10/($H10-$G10+1))
A11: D1 | B11: 8 | C11: 创建 OSS Bucket（ZRS + 版本控制 + 生命周期） | D11: 人员B | E11: G7 | F11: 1 | G11: 1 | H11: 1 | I11: =说明与总览!$B$21+VALUE(MID($A11,2,1))-1 | J11: =IF(AND($G11<=1,$H11>=1),"■■","") | K11: =IF(AND($G11<=2,$H11>=2),"■■","") | L11: =IF(AND($G11<=3,$H11>=3),"■■","") | M11: =IF(AND($G11<=4,$H11>=4),"■■","") | N11: =IF(AND($G11<=5,$H11>=5),"■■","") | O11: =IF(AND($G11<=6,$H11>=6),"■■","") | P11: =IF(AND($G11<=7,$H11>=7),"■■","") | Q11: =IF(AND($G11<=8,$H11>=8),"■■","") | R11: =IF(AND($G11<=9,$H11>=9),"■■","") | S11: =IF(AND($G11<=10,$H11>=10),"■■","") | T11: =IF(AND($G11<=11,$H11>=11),"■■","") | U11: =IF(AND($G11<=12,$H11>=12),"■■","") | V11: =IF(AND($G11<=13,$H11>=13),"■■","") | W11: =IF(AND($G11<=14,$H11>=14),"■■","") | X11: =IF(AND($G11<=15,$H11>=15),"■■","") | AB11: 策略与防盗链规则生效 | AC11: 已完成 | AD11: =IF($H11<$G11,0,$F11/($H11-$G11+1))
A12: D1 | B12: 9 | C12: 创建 ClickHouse 2 节点日志库（TTL 90 天） | D12: 人员B | E12: G7 | F12: 2 | G12: 2 | H12: 2 | I12: =说明与总览!$B$21+VALUE(MID($A12,2,1))-1 | J12: =IF(AND($G12<=1,$H12>=1),"■■","") | K12: =IF(AND($G12<=2,$H12>=2),"■■","") | L12: =IF(AND($G12<=3,$H12>=3),"■■","") | M12: =IF(AND($G12<=4,$H12>=4),"■■","") | N12: =IF(AND($G12<=5,$H12>=5),"■■","") | O12: =IF(AND($G12<=6,$H12>=6),"■■","") | P12: =IF(AND($G12<=7,$H12>=7),"■■","") | Q12: =IF(AND($G12<=8,$H12>=8),"■■","") | R12: =IF(AND($G12<=9,$H12>=9),"■■","") | S12: =IF(AND($G12<=10,$H12>=10),"■■","") | T12: =IF(AND($G12<=11,$H12>=11),"■■","") | U12: =IF(AND($G12<=12,$H12>=12),"■■","") | V12: =IF(AND($G12<=13,$H12>=13),"■■","") | W12: =IF(AND($G12<=14,$H12>=14),"■■","") | X12: =IF(AND($G12<=15,$H12>=15),"■■","") | AB12: 写入成功且 TTL 生效 | AC12: 已完成 | AD12: =IF($H12<$G12,0,$F12/($H12-$G12+1))
A13: D1 | B13: 10 | C13: 创建马尼拉 ACK Pro 集群（K8s 1.31 + Terway + RRSA + API Server 私网端点） | D13: 人员A | E13: 5,6 | F13: 2 | G13: 3 | H13: 3 | I13: =说明与总览!$B$21+VALUE(MID($A13,2,1))-1 | J13: =IF(AND($G13<=1,$H13>=1),"■■","") | K13: =IF(AND($G13<=2,$H13>=2),"■■","") | L13: =IF(AND($G13<=3,$H13>=3),"■■","") | M13: =IF(AND($G13<=4,$H13>=4),"■■","") | N13: =IF(AND($G13<=5,$H13>=5),"■■","") | O13: =IF(AND($G13<=6,$H13>=6),"■■","") | P13: =IF(AND($G13<=7,$H13>=7),"■■","") | Q13: =IF(AND($G13<=8,$H13>=8),"■■","") | R13: =IF(AND($G13<=9,$H13>=9),"■■","") | S13: =IF(AND($G13<=10,$H13>=10),"■■","") | T13: =IF(AND($G13<=11,$H13>=11),"■■","") | U13: =IF(AND($G13<=12,$H13>=12),"■■","") | V13: =IF(AND($G13<=13,$H13>=13),"■■","") | W13: =IF(AND($G13<=14,$H13>=14),"■■","") | X13: =IF(AND($G13<=15,$H13>=15),"■■","") | AB13: 集群 Running；**RRSA 已开启但不使用**（2026-10-05 裁定）；API Server 未暴露公网（newapi-master PUBLIC→PRIVATE 已复验） | AC13: 已完成 | AD13: =IF($H13<$G13,0,$F13/($H13-$G13+1))
A14: D2 | B14: 11 | C14: 创建 ECS 节点池 4×（三机型 [g9i, g8ine, g9ae]，实得 g9ae.2xlarge，跨 2 AZ、ESSD 300G、nofile 调优） | D14: 人员A | E14: 10 | F14: 4 | G14: 4 | H14: 5 | I14: =说明与总览!$B$21+VALUE(MID($A14,2,1))-1 | J14: =IF(AND($G14<=1,$H14>=1),"■■","") | K14: =IF(AND($G14<=2,$H14>=2),"■■","") | L14: =IF(AND($G14<=3,$H14>=3),"■■","") | M14: =IF(AND($G14<=4,$H14>=4),"■■","") | N14: =IF(AND($G14<=5,$H14>=5),"■■","") | O14: =IF(AND($G14<=6,$H14>=6),"■■","") | P14: =IF(AND($G14<=7,$H14>=7),"■■","") | Q14: =IF(AND($G14<=8,$H14>=8),"■■","") | R14: =IF(AND($G14<=9,$H14>=9),"■■","") | S14: =IF(AND($G14<=10,$H14>=10),"■■","") | T14: =IF(AND($G14<=11,$H14>=11),"■■","") | U14: =IF(AND($G14<=12,$H14>=12),"■■","") | V14: =IF(AND($G14<=13,$H14>=13),"■■","") | W14: =IF(AND($G14<=14,$H14>=14),"■■","") | X14: =IF(AND($G14<=15,$H14>=15),"■■","") | AB14: 节点 Ready 且跨 2 个可用区分布 | AC14: 已完成 | AD14: =IF($H14<$G14,0,$F14/($H14-$G14+1))
A15: D1 | B15: 12 | C15: 创建新加坡 VPC + vSwitch + NAT 网关 + EIP 池 | D15: 人员A | E15: 5,6 | F15: 2 | G15: 3 | H15: 3 | I15: =说明与总览!$B$21+VALUE(MID($A15,2,1))-1 | J15: =IF(AND($G15<=1,$H15>=1),"■■","") | K15: =IF(AND($G15<=2,$H15>=2),"■■","") | L15: =IF(AND($G15<=3,$H15>=3),"■■","") | M15: =IF(AND($G15<=4,$H15>=4),"■■","") | N15: =IF(AND($G15<=5,$H15>=5),"■■","") | O15: =IF(AND($G15<=6,$H15>=6),"■■","") | P15: =IF(AND($G15<=7,$H15>=7),"■■","") | Q15: =IF(AND($G15<=8,$H15>=8),"■■","") | R15: =IF(AND($G15<=9,$H15>=9),"■■","") | S15: =IF(AND($G15<=10,$H15>=10),"■■","") | T15: =IF(AND($G15<=11,$H15>=11),"■■","") | U15: =IF(AND($G15<=12,$H15>=12),"■■","") | V15: =IF(AND($G15<=13,$H15>=13),"■■","") | W15: =IF(AND($G15<=14,$H15>=14),"■■","") | X15: =IF(AND($G15<=15,$H15>=15),"■■","") | AB15: 新加坡 EIP 固定可出网 | AC15: 已完成 | AD15: =IF($H15<$G15,0,$F15/($H15-$G15+1))
... A59: D2 | B59: 56 | C59: 上游供应商白名单提交与生效确认（马尼拉 + 新加坡 EIP 池） | D59: 人员A | E59: 6,12 | F59: 1 | G59: 5 | H59: 5 | I59: =说明与总览!$B$21+VALUE(MID($A59,2,1))-1 | J59: =IF(AND($G59<=1,$H59>=1),"■■","") | K59: =IF(AND($G59<=2,$H59>=2),"■■","") | L59: =IF(AND($G59<=3,$H59>=3),"■■","") | M59: =IF(AND($G59<=4,$H59>=4),"■■","") | N59: =IF(AND($G59<=5,$H59>=5),"■■","") | O59: =IF(AND($G59<=6,$H59>=6),"■■","") | P59: =IF(AND($G59<=7,$H59>=7),"■■","") | Q59: =IF(AND($G59<=8,$H59>=8),"■■","") | R59: =IF(AND($G59<=9,$H59>=9),"■■","") | S59: =IF(AND($G59<=10,$H59>=10),"■■","") | T59: =IF(AND($G59<=11,$H59>=11),"■■","") | U59: =IF(AND($G59<=12,$H59>=12),"■■","") | V59: =IF(AND($G59<=13,$H59>=13),"■■","") | W59: =IF(AND($G59<=14,$H59>=14),"■■","") | X59: =IF(AND($G59<=15,$H59>=15),"■■","") | AB59: 8 个 EIP 均已提交并取得供应商生效确认 | AC59: 未开始 | AD59: =IF($H59<$G59,0,$F59/($H59-$G59+1))
A61: 人力负荷校验（每时段单人上限 4 人时；3 段/天 = 上午 09:00–13:00 / 下午 14:00–18:00 / 晚间 19:00–23:00；数据来自上表「每时段投入」列）
A62: 时段 | J62: S1 | K62: S2 | L62: S3 | M62: S4 | N62: S5 | O62: S6 | P62: S7 | Q62: S8 | R62: S9 | S62: S10 | T62: S11 | U62: S12 | V62: S13 | W62: S14 | X62: S15
A63: 人员A | J63: =SUMIFS($AD$4:$AD$59,$D$4:$D$59,"人员A",$G$4:$G$59,"<=1",$H$4:$H$59,">=1") | K63: =SUMIFS($AD$4:$AD$59,$D$4:$D$59,"人员A",$G$4:$G$59,"<=2",$H$4:$H$59,">=2") | L63: =SUMIFS($AD$4:$AD$59,$D$4:$D$59,"人员A",$G$4:$G$59,"<=3",$H$4:$H$59,">=3") | M63: =SUMIFS($AD$4:$AD$59,$D$4:$D$59,"人员A",$G$4:$G$59,"<=4",$H$4:$H$59,">=4") | N63: =SUMIFS($AD$4:$AD$59,$D$4:$D$59,"人员A",$G$4:$G$59,"<=5",$H$4:$H$59,">=5") | O63: =SUMIFS($AD$4:$AD$59,$D$4:$D$59,"人员A",$G$4:$G$59,"<=6",$H$4:$H$59,">=6") | P63: =SUMIFS($AD$4:$AD$59,$D$4:$D$59,"人员A",$G$4:$G$59,"<=7",$H$4:$H$59,">=7") | Q63: =SUMIFS($AD$4:$AD$59,$D$4:$D$59,"人员A",$G$4:$G$59,"<=8",$H$4:$H$59,">=8") | R63: =SUMIFS($AD$4:$AD$59,$D$4:$D$59,"人员A",$G$4:$G$59,"<=9",$H$4:$H$59,">=9") | S63: =SUMIFS($AD$4:$AD$59,$D$4:$D$59,"人员A",$G$4:$G$59,"<=10",$H$4:$H$59,">=10") | T63: =SUMIFS($AD$4:$AD$59,$D$4:$D$59,"人员A",$G$4:$G$59,"<=11",$H$4:$H$59,">=11") | U63: =SUMIFS($AD$4:$AD$59,$D$4:$D$59,"人员A",$G$4:$G$59,"<=12",$H$4:$H$59,">=12") | V63: =SUMIFS($AD$4:$AD$59,$D$4:$D$59,"人员A",$G$4:$G$59,"<=13",$H$4:$H$59,">=13") | W63: =SUMIFS($AD$4:$AD$59,$D$4:$D$59,"人员A",$G$4:$G$59,"<=14",$H$4:$H$59,">=14") | X63: =SUMIFS($AD$4:$AD$59,$D$4:$D$59,"人员A",$G$4:$G$59,"<=15",$H$4:$H$59,">=15")
A64: 人员B | J64: =SUMIFS($AD$4:$AD$59,$D$4:$D$59,"人员B",$G$4:$G$59,"<=1",$H$4:$H$59,">=1") | K64: =SUMIFS($AD$4:$AD$59,$D$4:$D$59,"人员B",$G$4:$G$59,"<=2",$H$4:$H$59,">=2") | L64: =SUMIFS($AD$4:$AD$59,$D$4:$D$59,"人员B",$G$4:$G$59,"<=3",$H$4:$H$59,">=3") | M64: =SUMIFS($AD$4:$AD$59,$D$4:$D$59,"人员B",$G$4:$G$59,"<=4",$H$4:$H$59,">=4") | N64: =SUMIFS($AD$4:$AD$59,$D$4:$D$59,"人员B",$G$4:$G$59,"<=5",$H$4:$H$59,">=5") | O64: =SUMIFS($AD$4:$AD$59,$D$4:$D$59,"人员B",$G$4:$G$59,"<=6",$H$4:$H$59,">=6") | P64: =SUMIFS($AD$4:$AD$59,$D$4:$D$59,"人员B",$G$4:$G$59,"<=7",$H$4:$H$59,">=7") | Q64: =SUMIFS($AD$4:$AD$59,$D$4:$D$59,"人员B",$G$4:$G$59,"<=8",$H$4:$H$59,">=8") | R64: =SUMIFS($AD$4:$AD$59,$D$4:$D$59,"人员B",$G$4:$G$59,"<=9",$H$4:$H$59,">=9") | S64: =SUMIFS($AD$4:$AD$59,$D$4:$D$59,"人员B",$G$4:$G$59,"<=10",$H$4:$H$59,">=10") | T64: =SUMIFS($AD$4:$AD$59,$D$4:$D$59,"人员B",$G$4:$G$59,"<=11",$H$4:$H$59,">=11") | U64: =SUMIFS($AD$4:$AD$59,$D$4:$D$59,"人员B",$G$4:$G$59,"<=12",$H$4:$H$59,">=12") | V64: =SUMIFS($AD$4:$AD$59,$D$4:$D$59,"人员B",$G$4:$G$59,"<=13",$H$4:$H$59,">=13") | W64: =SUMIFS($AD$4:$AD$59,$D$4:$D$59,"人员B",$G$4:$G$59,"<=14",$H$4:$H$59,">=14") | X64: =SUMIFS($AD$4:$AD$59,$D$4:$D$59,"人员B",$G$4:$G$59,"<=15",$H$4:$H$59,">=15")
A65: 负荷结论 | B65: {=IF(COUNTIF(J63:X64,">4")>0,"存在超载时段，需调整排期","负荷均衡：每人每时段 ≤ 4 人时")}
A66: 总投入(人时) | B66: =SUM($F$4:$F$59) | C66: 总产能(人时，2 人 × 5 天 × 3 段 × 4 小时) | D66: =2*5*3*4 | E66: =IF($B66<=$D66,"工期可行：总投入未超产能，保留 7 人时缓冲（利用率 94.2%）","超出产能，须延长工期或裁剪范围")
A68: T-5 / T-3 前置门禁清单（等待型与研发型前置，不占用实施工期人力；G1–G7 与 G9 为 T-5 前置，G8 与 G10–G13 为 T-3 前置；全部完成才允许 D1 启动）
A69: 编号 | B69: 前置事项 | C69: 类别 | D69: 负责角色 | E69: 发起时点 | F69: 最长等待 | G69: 门禁作用
A70: G1 | B70: 注册阿里云国际站账号并发起企业实名认证 | C70: 账号 | D70: 项目负责人 | E70: T-5（说明与总览!$B$22） | F70: 1–2 工作日 | G70: 未实名无法购买 ECS/RDS，直接阻塞 D1。（对应账号表 #1/#2）
A71: G2 | B71: 提交资源配额工单（ECS vCPU / EIP / ALB / RDS / RDS 代理 / PgBouncer / GTM） | C71: 提交资源配额工单（ECS vCPU / EIP / ALB / RDS / GTM；**托管 PgBouncer 无需单独配额**） | D71: 运维负责人 | E71: T-5 | F71: 2–3 工作日（关键路径） | G71: 未批复无法创建节点池与出口 EIP。（对应账号表 #7）
A72: G3 | B72: 开通后付费、绑定支付方式、设置预算告警 | C72: 账号 | D72: 财务 | E72: T-5 | F72: 当日 | G72: 未开通无法下单。（对应账号表 #3）
A73: G4 | B73: 域名注册 + 实名认证 + NS 指向云解析并 dig 验证 | C73: 域名 | D73: 项目负责人 | E73: T-5 | F73: 24–48h 生效 | G73: NS 未生效则 D1 接入层无法验证。（对应账号表 #13/#14/#15）
A74: G5 | B74: SSL 通配符证书申请（*.likha.hk，TLS 1.2+1.3） | C74: 证书 | D74: 运维负责人 | E74: T-5 | F74: 1–24h | G74: 无证书则 ALB/WAF HTTPS 不可用。（对应账号表 #17）
A75: G6 | B75: 域名解析记录、GTM 地址池与证书部署配置模板就绪 | C75: 接入 | D75: 运维负责人 | E75: T-5 | F75: 当日 | G75: 与 ALB/WAF 的创建时序对齐（原方案 D1 部署证书时 ALB 尚未创建；本版修正为任务 #40 在 D5 下午段（S14）执行，位于 ALB #19 / WAF #20 / 新加坡 ALB #25 全部就绪之后）。（对应账号表 #16/#18）
A76: G7 | B76: 开通全部云产品（网络/计算/数据/接入/观测/运维访问面） | C76: 产品 | D76: 运维负责人 | E76: T-5 | F76: 当日 | G76: 国际站需逐产品开通，未开通则无法下单。（对应账号表 #8–#12）
A77: G8 | B77: 代码侧补建项【完成并合并】：/healthz、/readyz、/metrics、限流降级改造（Redis 故障降级放行而非 fail-closed） | C77: 研发 | D77: 后端负责人 | E77: T-3 | F77: 1–2 工作日 | G77: 未完成则 SLA 99.95% 不成立（impl_deploy.md 8.2 最低配置 / R-05）；原 v2.0 仅要求「排期确认」，本版改为「必须完成」。属研发独立排期，不计入部署人时。
A78: G9 | B78: RAM 用户 / 资源组 / 成本标签 / MFA / ActionTrail 预建 | C78: 账号 | D78: 安全负责人 | E78: T-5 | F78: 当日 | G78: 最小权限与审计是上线检查表必查项。（对应账号表 #4/#5/#6）
A79: G10 | B79: 备 region 容量方案与配额确认（新加坡实批按量 96 vCPU、HPA 2–20、节点池自动伸缩 2–12；本期仅 PH 备，不含泰国备） | C79: 容量 | D79: 运维负责人 | E79: T-3 | F79: 当日 | G79: 未确认则备 region 无法满足「单站点全量接管 = 被接管站点 maxReplicas 13 × 1.5 = 19.5 → 20 副本」（容量下限 8 节点 / 64 vCPU，实况上限 12 节点 / 96 vCPU），M4 与 SLA 不达标。（对应账号表 #7 第二批工单）
A80: G11 | B80: 连接数预算与 PgBouncer / RDS 代理方案确认（含三条不变量 I-1/I-2/I-3） | C80: 数据 | D80: 后端负责人 | E80: T-3 | F80: 当日 | G80: 主站扩到 16 实例时 300 × 16 = 4800 连接会打爆 PG（impl_deploy.md 8.5）。（对应账号表 #9）
... A82: G13 | B82: staging / perf 环境方案确认（位置、规格、三数据库矩阵与压测矩阵承载方式） | C82: 环境 | D82: 运维 + 后端 | E82: T-3 | F82: 当日 | G82: 未确认则任务 #33 压测与 #45 无落点；与「新加坡不部署 RDS」红线的口径冲突需一并澄清。
A83: G0 门禁：以上 G1–G13 任一项未完成，D1 不得启动。其中 G1–G7 与 G9 为 T-5 前置（等待型），G8 与 G10–G13 为 T-3 前置（研发/确认型）。本版为 5 天冲刺口径：2 人全职、每天 3 个工作段（含晚间加班段）、单人每段 ≤ 4 人时，15 段共 120 人时产能、投入 113 人时（94.2%），仅余 7 人时缓冲（约 1.75 个时段/人），任一人阻塞或任一外部依赖延期即直接顺延，无内部消化空间。若无法接受该风险，可选方案：① 新增第 3 人（约 +60 人时）把利用率降到 63%；② 按「里程碑与验收」裁剪预案降级范围；③ 回退 9 天口径（78% 利用率、31 人时缓冲）。

Sheet 里程碑与验收
A1: 里程碑门禁、验收证据、SLA 指标口径、关键风险与工期裁剪预案
A3: 里程碑 | B3: 偏移(日，D1=0) | C3: 目标日期 | D3: 通过标准 | E3: 验收证据 | F3: 负责角色 | G3: 状态 | H3: 备注
A4: G0 前置门禁通过 | B4: -5 | C4: =说明与总览!$B$21+B4 | D4: T-5 = 前置启动日。G1–G13 全部完成：账号可下单、配额已批复、域名 NS 生效、证书已签发、代码侧补建完成、备 region 容量与连接数方案确认、SLA 口径与交付范围书面确认、staging/perf 方案确认 | E4: 实名认证截图、配额批复工单号、dig NS 结果、证书 ID、G8 代码合并记录、G12 确认邮件 | F4: 项目负责人 | G4: 未开始 | H4: 未通过则 5 天工期不可达，必须顺延（D1 不得启动）。决策留痕（2026-09-24）：前置启动日 T-5 = 2026-09-23 编制时已过，本次维持原基准不变、不顺延 D1；G1–G13 未在本基准内闭环时，仍按本节门禁规则顺延。
A5: M1 D1 晚间结束：合规与数据底座就绪 | B5: 0 | C5: =说明与总览!$B$21+B5 | D5: 账号合规收口（G0 收口完成）、马尼拉网络底座（VPC / 4 组 vSwitch / NAT / EIP 池）可用、ACK Pro 集群创建完成、RDS 主备 + Tair + ClickHouse + OSS + 双地域 ACR 已创建、RDS 备份策略（PITR）生效、域名 NS 复核通过 | E5: VPC/EIP 清单、ACK 集群详情、RDS 实例详情、Tair 与 CH 连接测试记录、备份任务记录、dig NS 结果 | F5: 人员A / 人员B | G5: 部分达成（2026-10-12：网络底座 / ACK / RDS / Tair / CK / OSS / ACR / 备份策略 / NS 复核均已完成；G0 未整体闭环，「双地域 ACR」按 F8 改单地域） | H5: D1 三个时段共完成 13 项任务；RDS 主备跨可用区，备份任务已有可恢复时间点
A6: M2 D2 晚间结束：计算底座与主库就绪 | B6: 1 | C6: =说明与总览!$B$21+B6 | D6: 节点池实得 4×ecs.g9ae.2xlarge 跨 2 AZ Ready（三机型列表 [g9i, g8ine, g9ae]）、Namespace/ConfigMap/Secret（**手工 Opaque Secret；不使用 KMS/RRSA/ExternalSecret**）就绪、master Deployment 迁移幂等（连续两次结果一致）、马尼拉 ALB + 健康检查就绪、RDS 内置托管 PgBouncer 与连接数预算落地、运维访问面（kubeconfig / RAM→RBAC / API Server 端点 / 堡垒机）可用、PITR 恢复演练记录 RPO/RTO、上游 8 个 EIP 白名单提交 | E6: 节点列表、迁移两次的幂等验证记录、ALB 健康检查截图、连接数预算表、PITR 演练报告、白名单提交回执、kubeconfig 与端点策略截图 | F6: 人员A / 人员B | G6: 部分达成（2026-10-12：节点池 4 台跨 2 AZ、手工 Opaque Secret、master 迁移幂等、马尼拉 ALB+健康检查、托管 PgBouncer、运维访问面均已完成） | H6: master 迁移必须连续两次结果一致；PgBouncer cl_waiting 无堆积；PgBouncer 须先于应用连库就位（任务 #41 早于 #18 完成配置收敛）
A7: M3 D3 晚间结束：接入层与主站点灰度就绪 | B7: 2 | C7: =说明与总览!$B$21+B7 | D7: stable 4 副本跨 AZ Ready（PDB 70% + HPA 4–13 + Pod 反亲和）、canary Deployment 就绪（✅ 2026-10-12 V1–V6 全过）、PH 备 Deployment/Service 就绪（⚠ 实况：任务 25 的 SG ALB 已于 2026-10-12 闭合，V4 会话互通仍未实测 ⇒ 仍记**部分交付**）、新加坡 ACK 集群与节点池创建完成、GTM 实例/地址池/健康探测生效（先只挂马尼拉；⚠ 任务 21 2026-09-30 裁定挂起，仍未创建）、安全组与数据库白名单逐条核对通过、staging/perf 环境跑通最小三数据库冒烟 | E7: Pod 跨 AZ 分布截图、GTM 探测记录、安全组核对表、三库矩阵用例结果、新加坡集群详情 | F7: 人员A / 人员B | G7: 部分达成（2026-10-12：stable 副本/PDB/HPA、canary V1–V6、新加坡 ACK 与 ALB（含 443+TLS）、安全组与白名单核对已完成；GTM 仍挂起、任务 28 V4 未实测、staging/perf 未建） | H7: 此时系统已具备灰度发布条件；WAF 接入与主站 HPA 落在 D4/D5（任务 #20 / #43）
A8: M4 D4 晚间结束：演练通过且可观测就绪 | B8: 3 | C8: =说明与总览!$B$21+B8 | D8: WAF 3.0 接入 + CC 策略生效（⏸ 2026-10-12 F15：本轮不采购 WAF ⇒ 该项从 M3 通过标准移除，入口层无 L7 防护为知情接受缺口）、灰度发布演练（5→20→50→100 与回滚）通过、备 region 公网读写马尼拉主库成功（连接 RTT ≤ 70 ms）、备 region 接管演练与主库切换演练通过、容量压测达标（并发 SSE 1500 / 管理面 800 QPS）、**ack-goatscaler 配置就绪（扩节点动作未实测）**、新加坡 ALB 就绪、SLS/ARMS/Grafana/站点拨测可见、上线前安全核查无高危项、备 region 链路拨测与告警生效 | E8: WAF 拦截记录与合规判分、灰度演练记录、连接测试记录（含 sslmode=verify-full）、演练报告（含 RTO/RPO）、压测报告、安全核查清单、看板与拨测截图 | F8: 人员A / 人员B | G8: 未开始（⏸ 2026-10-12 F15：WAF 本轮不采购，该项已从 M3 判据移除；灰度/接管/主库切换演练与压测均未执行；观测面任务 26 已于 2026-10-10 4/4 闭环、新加坡 ALB 已就绪） | H8: 阻断线：RTT > 100 ms 或连接失败率 > 0.1%（5 分钟滑动窗口）时暂不挂入 GTM；接管容量 = 主站 maxReplicas **13 × 1.5 = 19.5 → 20 副本**（HPA 2–20 于 D5 与上线同步落地并验证）
A9: M5 D5 晚间结束：正式上线并完成移交 | B9: 4 | C9: =说明与总览!$B$21+B9 | D9: 主站 HPA **4–13** 与备 region HPA **2–20** 落地并验证、证书正式部署至 ALB/WAF/DCDN（SNI 校验通过）、上线检查表通过并完成正式上线（D5 S13）、备 region Tair 预热与支付回调源 IP 白名单验证、SLO/错误预算看板与告警通道就绪、上游 RPM/TPM 配额台账与成本量化表交付、运维移交完成 | E9: HPA 扩容记录、证书 ID 与 SNI 校验结果、上线检查表、看板截图、配额台账、成本量化表、Runbook/应急预案/值班表 | F9: 人员A / 人员B | G9: 未开始 | H9: 正式上线安排在 D5 S13（上午段），上线后 1 小时值守观察；D5 下午/晚间段为上线后收尾与移交
A11: 关键风险与前置依赖（2 人 / 5 天冲刺口径）
A12: 风险 / 前置依赖 | B12: 影响 | C12: 应对措施 | D12: 责任角色 | E12: 触发信号 | F12: 风险等级 | G12: 剩余风险 | H12: 备注
A13: 企业实名认证或配额审批未在 T-5 完成 | B13: 工期直接不可达，全案顺延 | C13: T-5 上午立即提交；每日 18:00 跟进工单；先用已批复配额创建 VPC/ALB 等低配额资源 | D13: 项目负责人 | E13: T-5 日落前未通过 / 未批复 | F13: 高 | G13: 工期顺延 2–3 天 | H13: 唯一的外部不可控项，已在 G1/G2 列为门禁。决策留痕（2026-09-24）：T-5 = 2026-09-23 已过，本期不改基准、不顺延 D1，接受该项剩余风险；T-5 后每日 18:00 跟进而未批复的，D1 即顺延（顺延不改变工期仍为 5 天的结论）。
A14: 备 region 配额（新加坡 ≥64 vCPU）未批复 | B14: 备 region 无法满足「接管 = 主站 maxReplicas 13 × 1.5 = 19.5 → 20 副本」，M4 与 SLA 不达标 | C14: 与主站点配额分开申请并在 T-3 前跟进；未批复时按 HPA max 12 副本（而非 20）交付并书面记录 SLA 降级——节点池实况上限 12 节点 / 96 vCPU（12 副本仅需 24 vCPU） | D14: 运维负责人 | E14: T-3 配额工单未批复 | F14: 高 | G14: SLA 口径需下调或追加预算 | H14: G10 门禁
A15: 代码侧补建项（/healthz、/readyz、/metrics、限流降级）未在 T-3 完成 | B15: 探针不准确、监控缺失、Tair 故障时 fail-closed 直接 5xx → SLA 99.95% 不成立 | C15: T-3 前完成开发与合并（G8）；未完成则 D1 不得启动，或用 /api/status + TCP 临时替代并接受指标置信度下降 | D15: 后端负责人 | E15: T-3 合并记录缺失或探针仍指向 /api/status | F15: 高 | G15: 可用性指标置信度下降 | H15: 属研发工作量，不计入部署 113 人时；本版为「必须完成」的 T-3 门禁（G8）
A16: 仅 2 人且无人员冗余（5 天冲刺下风险升级） | B16: 任一人阻塞或请假，关键路径断裂导致整体延期 | C16: 明确 A/B 分工并互备关键命令；每日 3 次短站会（每段结束 10 分钟）同步阻碍项；关键变更与上线操作集中在 S1/S2，晚间加班段只排低风险任务。已决策（2026-09-24）：本期不增加第 3 人。本版缓冲仅 7 人时（约 1.75 段/人），无法覆盖任一人单日缺席，人力冗余风险改由以下方式收敛：① A/B 关键命令互备，每段结束 10 分钟交接并留书面记录；② 单日任务完成率 < 80% 即触发「工期裁剪预案」，自第 1 项（DCDN 延后）起顺序降级；③ 任一人员缺席当天即停止关键变更，只执行可回退任务并按 G0 规则顺延。 | D16: 项目负责人 | E16: 单日任务完成率 < 80% | F16: 中 | G16: 接受（本期不加第 3 人）；触发时按工期裁剪预案降级交付范围兜底 | H16: A 负责网络/接入，B 负责数据/应用；5 天口径下缓冲由 31 人时降至 7 人时。决策留痕（2026-09-24）：不增加第 3 人，7 人时缓冲的剩余风险由裁剪预案与 A/B 互备兜底。
A17: 域名 NS 生效需 24–48 小时 | B17: D1 接入层无法验证，顺延 D3 | C17: T-5 完成 NS 托管并 dig 验证；未生效前先用 ALB 默认域名完成配置验证 | D17: 运维负责人 | E17: dig 返回非阿里云 DNS | F17: 中 | G17: 顺延 1 天 | H17: 已在 G4 列为门禁
A18: 新加坡 → 马尼拉 RDS 公网延迟或抖动 | B18: 备 region 接管期写延迟抬升，影响体感 | C18: D4 完成实测并留存基线（任务 #30 在 D4 上午段）；RTT > 100 ms 或失败率 > 0.1%（5 分钟窗口）时暂不把备 region 挂入 GTM 备地址池；建议评估以 CEN / VPC 对等替代公网直连 | D18: 人员B | E18: 拨测 RTT 超标 | F18: 中 | G18: 接管期写入 P99 抬升 ≤ 80ms | H18: 链路不健康时阻断接管（任务 #39）
A19: 备 region 误以 master 启动导致并发迁移同一 schema | B19: 迁移冲突、锁表甚至数据损坏 | C19: 备 region 固定 NODE_TYPE=slave 并纳入部署门禁校验；备 region 不授予迁移权限账号 | D19: 人员B | E19: 备 region 日志出现 AutoMigrate | F19: 中 | G19: 可控（门禁拦截） | H19: 红线项
A20: 双写风险（主站点与备 region 同时写同一主库） | B20: 计费对账分裂、额度超扣或重复扣 | C20: GTM 健康探测 + 主站点 ALB 摘流共同收口；禁止本地库、只读副本与 DTS 链路；上线前演练验证 | D20: 人员A | E20: 同一 request_id 出现双写记录 | F20: 中 | G20: 可控（架构层面消除） | H20: 红线项
A21: PgBouncer / RDS 代理成为新增单点 | B21: 池故障时全站不可用 | C21: **RDS 内置托管 PgBouncer（不自建，无 3 副本 + PDB 形态）**；应用侧自动重连 + RetryTimes；预置「回退直连」应急 DSN 与演练 | D21: 人员B | E21: 池 cl_waiting 持续堆积或 query_wait_timeout 报错 | F21: 中 | G21: 单副本 ≤ 30s 恢复；全层回退分钟级 | H21: impl_deploy.md 8.4 故障域表已纳入
A22: 跨区公网链路（未走 CEN / VPC 对等） | B22: 备 region → 主库链路概率性劣化，且公网暴露面更大 | C22: T-3 评估 CEN / VPC 对等替代方案（需补开通项）；未替代前保留公网 + IP 白名单 + verify-full 收敛面 | D22: 人员A | E22: 公网段抖动、连接失败率上升 | F22: 中 | G22: 接管成功率受影响 | H22: 架构改进项，优先级最高
A23: 上游渠道 RPM / TPM 配额不足 | B23: 网关核心容量约束，压测结论与真实吞吐不符 | C23: T-8 前完成各渠道配额盘点并建立台账（任务 #51）；限流参数与配额对齐；必要时补充供应商账号 | D23: 人员B | E23: 压测出现大量 429 / 渠道自动禁用告警 | F23: 中 | G23: 实际吞吐低于验收口径 | H23: 原方案完全未评估上游配额
